Workbook

Sheet 서비스 Master
C1: 1 | D1: 2 | E1: 3 | F1: 4 | G1: 5 | H1: 6 | I1: 7 | J1: 8 | K1: 9 | L1: 10 | M1: 11 | N1: 12 | O1: 13 | P1: 14 | Q1: 15 | R1: 16 | S1: 17 | T1: 18 | U1: 19 | V1: 20 | W1: 21 | X1: 22 | Y1: 23 | Z1: 24 | AC1: 26 | AD1: 27 | AE1: 28 | AF1: 29 | AG1: 30 | AH1: 31 | AI1: 32 | AJ1: 33 | AK1: 34 | AP1: 35 | AQ1: 36 | AR1: 37 | AS1: 38 | AT1: 39 | AU1: 40 | AV1: 41 | AX1: 42 | AZ1: 42
I2: Appl. 담당 | N2: 고객사 IT 담당 | Q2: Infa 담당자(SK/협) | W2: Front-End | Y2: Back-End | AB2: 운영환경 | AE2: 자동화도구 | AH2: 모니터링 | AL2: 시스템 활용도 | AP2: 비고(특이사항) | AQ2: 서비스 대상
A3: No | B3: 구분 | C3: 시스템명 | D3: 시스템 구분 번호 | E3: 설명 | F3: 당사 관리 범위 | G3: 서비스 등급 | H3: 서비스 수준 | I3: 담당 회사 | J3: 담당 부서 | K3: 담당 팀장 | L3: 담당자 | M3: 협력 | N3: 담당 부서 | O3: 담당 팀장 | P3: 담당자 | Q3: 서버(OS) | R3: MW | S3: DB | T3: NW | U3: 서비스 오픈일 | V3: SI/솔루션 | W3: 언어 | X3: Framework | Y3: 언어 | Z3: Framework | AA3: Middleware | AB3: Cloud구분 | AC3: CSP | AD3: DB | AE3: 형상관리 | AF3: 코드 (개발F/W) | AG3: 배포 | AH3: Infra (서버,DB,MW) | AI3: N/W | AJ3: APM | AK3: ITGC여부 | AL3: 전체 사용자수 | AM3: 활성 사용자수 | AN3: 오너 부서 | AO3: 활용 주기 | AQ3: GC | AR3: 파마 | AS3: 플라즈마 | AT3: MU | AU3: 엔티스 | AV3: 대정 | AW3: DY | AX3: BS | AY3: BS Share 비율 (케미칼 : 바사) | AZ3: BS Share 비고
A4: 1 | B4: 경영지원 | C4: HR G/W HCM G/W | D4: =A4 -> 1 | E4: [시스템 개요] HCM 클라우드 인사관리시스템과 기간/레가시간 데이터 중계 시스템 [주요 기능] 1. HCM 의 인사 및 조직 정보 및 변경 내역을 Daily 로 ERP 및 Legacy 시스템으로 I/F 2. GC, LS, 플라즈마, BS, DY 공통으로 사용 중임 | F4: Appl | I4: C&C | J4: 제조MIS서비스2팀 | K4: 정철우 | L4: 조래옥 | M4: 유원혁 | N4: DT팀 | O4: 두상헌 | P4: 김햇빛 | U4: 2020 | V4: SI 개발 | W4: C# 5.0 | X4: .Net 4.5 | Y4: C# 5.0 | Z4: .Net 4.5 | AB4: N | AD4: MSSQL 2019 | AE4: bitbucket | AF4: .Net 4.5 | AG4: Jenkins | AJ4: Datadog | AQ4: O | AR4: O | AS4: O | AT4: O | AU4: O | AV4: O | AW4: O | AX4: O | AY4: 0.647:0.335 | AZ4: 인력/서비스 Share : 유원혁 M, 25년 : 0.642:0.338
A5: 2 | C5: MDM 시스템 | D5: =A5 -> 2 | E5: [시스템 개요] 전사기준정보(고객,공급업체,제품,원부재료,기자재,설비) 주요 코드를 생성하여 ERP등 필요 시스템에 넘겨주는 시스템 [주요 기능] 1. 마스터 코드 생성 | F5: Appl | I5: C&C | J5: Plant서비스팀 | K5: 이동호 | L5: 이용재 | M5: 민준홍 | N5: DT팀 | O5: 두상헌 | P5: 유현상 | U5: 2021 | V5: 솔루션 | W5: Javascript ES5 / JSP 2.3 | X5: jQuery 1.11.1 / Ext JS 7.4.0.42 | Y5: Java 1.8 | Z5: Spring 4.3.22 | AB5: Y | AC5: AWS | AD5: MSSQL 2017 | AE5: bitbucket | AF5: Java 1.8 | AG5: Jenkins | AJ5: Datadog | AK5: Y | AQ5: O
A6: 3 | C6: MDM 유지보수 | D6: =A6 -> 3 | E6: 솔루션 유지보수 | F6: Appl | V6: N/A | AP6: 솔루션 유지보수
A7: 4 | C7: PMO | D7: =A7 -> 4 | E7: [시스템 개요] 내부통제 및 품질관리 Legacy PMO | F7: Appl | I7: C&C | J7: 제조MIS서비스2팀 | K7: 정철우 | L7: 조래옥 | M7: 최문석/홍명기 | N7: DT팀 | O7: 두상헌 | P7: 민석홍 | V7: N/A | AX7: O | AY7: 0.647:0.335 | AZ7: 인력 Share : 최문석 M, 25년 : 0.642:0.338
A8: 5 | C8: RPA | D8: =A8 -> 5 | E8: [시스템 개요] RPA(Robotic Process Automation). 반복적이고 규칙적인 업무를 소프트웨어 봇이 자동화하여 수행하는 시스템 현재 75개 프로세스 운영 중 [주요 기능] 1. 업무 프로세스 자동화 2. 프로세스 스케쥴링 3. 이메일 트리거 실행 | F8: Appl | I8: C&C | J8: 제조MIS서비스2팀 | K8: 정철우 | L8: 이인 | M8: 김건휘 | N8: DT팀 | O8: 두상헌 | P8: 김햇빛 | U8: 2008 | V8: 솔루션 | W8: N/A | X8: N/A | Y8: N/A | Z8: A360 | AB8: Y | AC8: AWS | AD8: MSSQL 2017 | AE8: A360 | AF8: A360 | AG8: A360 | AQ8: O | AR8: O
A9: 6 | C9: UI/UX | D9: =A9 -> 6 | E9: [시스템 개요] 웹 기획 및 웹 퍼블리싱/디자인 | F9: Appl | I9: C&C | J9: 제조MIS서비스2팀 | K9: 정철우 | L9: 조래옥 | M9: 양미라 | N9: DT팀 | O9: 두상헌 | P9: 김햇빛 | V9: N/A
A10: 7 | C10: 구)e-HR | D10: =A10 -> 7 | E10: [시스템 개요] 케미칼 과거 인사시스템 [주요기능] 1. 케미칼 과거 인사데이터 2. 케미칼 과거 연말정산 데이터 보관 | F10: Appl | I10: C&C | J10: 제조MIS서비스2팀 | K10: 정철우 | L10: 조래옥 | M10: 정정배/김기정 | N10: DT팀 | O10: 두상헌 | P10: 김햇빛 | U10: 2001 | V10: SI 개발 | W10: JSP 2.0 | X10: JDK 1.4.2 | Y10: Java 1.8 | Z10: JDK 1.4.2 | AB10: N | AD10: Oracle 10g | AE10: - | AF10: Java 1.8 | AG10: - | AQ10: O | AR10: O | AS10: O | AT10: O | AU10: O | AV10: O | AW10: O
A11: 8 | C11: 데이터레이크 | D11: =A11 -> 8 | E11: [시스템 개요] 원천시스템의 데이터를 분석의 목적으로 한곳에 모아두는 정보계 시스템 [주요 기능] 1. 원천 시스템 데이터 Gathering 2. 데이터 분석 | F11: Appl | I11: C&C | J11: 제조MIS서비스2팀 | K11: 정철우 | L11: 조래옥 | M11: 경규민 | N11: DT팀 | O11: 두상헌 | P11: 민석홍 | U11: 2022 | V11: SI 개발 | W11: N/A | X11: N/A | Y11: Python 3.9 | Z11: Apache Hudi 0.10.1 | AB11: Y | AC11: AWS | AD11: AWS S3 | AE11: - | AF11: Python | AG11: - | AQ11: O | AR11: O | AW11: O
A12: 9 | C12: 데이터포털 | D12: =A12 -> 9 | E12: [시스템 개요] 데이터레이크에 수집데이터 바탕으로 Web상에서 데이터 분석 하는 시스템 | F12: Appl | I12: C&C | J12: 제조MIS서비스2팀 | K12: 정철우 | L12: 조래옥 | M12: 구본호 | N12: DT팀 | O12: 두상헌 | P12: 민석홍 | U12: 2023 | V12: SI 개발 | W12: typescript/Javascript/html/scss | X12: Angular 13.3.12 | Y12: Javascript / Typescript | Z12: NestJS 11.1.5 | AA12: Node.js 24.4.2 | AB12: Y | AC12: AWS | AD12: Mongo DB 5.0.24 | AE12: - | AF12: Javascript | AG12: 수동 배포 | AP12: 솔루션 유지보수 | AQ12: O | AR12: O
C13: 표준관리시스템 | D13: =A13 -> 0 | E13: [시스템 개요] 데이터레이크에 수집데이터 바탕으로 Web상에서 데이터 분석 하는 시스템` | F13: Appl | I13: C&C | J13: 제조MIS서비스2팀 | K13: 정철우 | L13: 조래옥 | M13: 구본호 | N13: DT팀 | O13: 두상헌 | P13: 민석홍 | U13: 2023 | V13: SI 개발 | W13: Javascript/JSP 2.5 | X13: Ext JS 4.2.1 | Y13: Java 1.8 | Z13: Spring 4.2.6 | AB13: N | AD13: PostgreSQL 17 | AE13: - | AG13: 수동 배포 | AP13: 솔루션 유지보수 | AQ13: O | AR13: O
A14: 10 | C14: 데이터포털 유지보수 | D14: =A14 -> 10 | E14: 솔루션 유지보수 | F14: Appl | V14: N/A | AP14: 솔루션 유지보수 | AQ14: O | AR14: O
A15: 11 | C15: 법무포탈 | D15: =A15 -> 11 | E15: [시스템 개요] 기업법무 분야의 계약, 자문, 인장 업무에 대한 고객사 내 표준 프로세스 및 관리업무를 위한 법무관리시스템 [주요 기능] 1. 계약관리 2. 자문관리 3. 인장날인 관리 4. 전자인증서 관리 | F15: Appl | I15: C&C | J15: 제조MIS서비스2팀 | K15: 정철우 | L15: 조래옥 | M15: 김아현 | N15: DT팀 | O15: 두상헌 | P15: 김햇빛 | U15: 2022 | V15: SI 개발 | W15: Javascript ES5 / JSP 2.3 | X15: jQuery 1.12.4 | Y15: Java 1.8 | Z15: 자체개발 | AB15: Y | AC15: AWS | AD15: MSSQL 2017 | AE15: bitbucket | AF15: Java 1.8 | AG15: Jenkins | AJ15: Datadog | AQ15: O | AR15: O | AS15: O | AT15: O | AU15: O | AV15: O | AX15: O | AZ15: 서비스 Share : 비용분담 X, 과거 데이터 조회용
A16: 12 | C16: 스마트오피스 서비스 | D16: =A16 -> 12 | E16: [시스템 개요] ECO Lab 7층/8층 및 연구동 자율좌석 및 회의실 예약 시스템 [주요 기능] 1. 좌석예약시스템 2. 회의실 예약시스템 | F16: Appl | I16: C&C | J16: 제조MIS서비스2팀 | K16: 정철우 | L16: 조래옥 | M16: 변영운 | N16: DT팀 | O16: 두상헌 | P16: 김햇빛 | U16: 2021 | V16: 솔루션 | W16: Javascript ES6 / JSP 2.3 | X16: jQuery 3.6.0 | Y16: Java 1.8 | Z16: Spring 4.0.9 | AB16: Y | AC16: AWS | AD16: MariaDB | AF16: Java 1.8 | AG16: sftp | AQ16: O | AR16: O | AS16: O | AW16: O
A17: 13 | B17: 기업문화 | C17: ESG Data HUB | D17: =A17 -> 13 | E17: [시스템 개요] 전사 ESG관련 Data 취합 및 관리 [주요 기능] ESG 관련 대시보드 기후 데이터 관리 ESG 일반 데이터 관리 | F17: Appl | I17: C&C | J17: 제조MIS서비스2팀 | K17: 정철우 | L17: 조래옥 | M17: 한준호 | N17: DT팀 | O17: 두상헌 | P17: 김햇빛 | U17: 2023 | V17: 솔루션 | W17: JSP | X17: Bootstrap 4.0 | Y17: Java 1.8 | Z17: 전자정부 | AB17: Y | AC17: AWS | AD17: MSSQL 2017 | AE17: Bitbucket | AF17: Java & JSP | AG17: Jenkins | AQ17: O
A18: 14 | C18: 톡톡 스마트오피스 앱 | D18: =A18 -> 14 | E18: [시스템 개요] 톡톡 모바일 App. Store 의 스마트오피스 App. 을 통하여 마케팅 허브에 Link 된 모바일 시스템 활용할 수 있는 시스템 [주요 기능] 1. 스마트오피스 접속 2. 모바일 톡톡 연동 3. PG 카드수금, 전자증빙 App 연동 등 Native 기능 제공 | F18: Appl | I18: C&C | J18: 제조MIS서비스2팀 | K18: 정철우 | L18: 조래옥 | M18: 정상률 | N18: DT팀 | O18: 두상헌 | P18: 김햇빛 | U18: 2020 | V18: SI 개발 | W18: Android (Kotlin) / IOS (Swift 5) | X18: SDK 29 / Deployment Target 13.0 | Y18: N/A | Z18: N/A | AB18: N | AD18: - | AE18: - | AF18: Android (Kotlin) & IOS (Swift (4)) | AG18: - | AR18: O | AS18: O | AX18: O | AZ18: 서비스 Share : 비용분담 X
A19: 15 | B19: 영업 | C19: CRM (S.Square) | D19: =A19 -> 15 | E19: SK케미칼 서비스 종료 | F19: Appl | I19: C&C | J19: 제조MIS서비스2팀 | K19: 정철우 | L19: 이인 | M19: 박도현 | N19: DT팀 | O19: 두상헌 | P19: 김햇빛 | U19: 2017 | V19: SI 개발 | AB19: Y | AC19: AWS | AD19: MSSQL 2017 | AE19: bitbucket | AF19: C#/.Net 4.5 | AG19: Jenkins | AQ19: O
A20: 16 | C20: EOS G/W | D20: =A20 -> 16 | E20: [시스템 개요] MIS와 EOS 간 인터페이스 업무 처리 시스템 [주요 기능] 1. LS 영업 시스템의 주요 관리 로직 내역 I/F w/ 도매상 EOS Sys. 2. 인사, 부서 마스터 I/F w/ HCM Sys. | F20: Appl | I20: C&C | J20: 제조MIS서비스2팀 | K20: 정철우 | L20: 이인 | M20: 김기정 | N20: DT팀 | O20: 두상헌 | P20: 박상진 | U20: 2020 | V20: SI 개발 | W20: N/A | X20: N/A | Y20: C# 5.0 | Z20: .Net 4.5 | AB20: N | AD20: - | AE20: bitbucket | AF20: .Net 4.5 | AG20: Jenkins | AP20: EOS <-> LS-MIS, 인터페이스 GW (DB는 LS-MIS) | AR20: O | AX20: O | AZ20: 서비스 Share : 비용분담 X
A21: 17 | C21: SIRS | D21: 17 | E21: [시스템 개요] 제품 안정성 관련 제품의 사용 후 보고된 이상사례 정보 공유 관리 시스템 [주요 기능] 1. 제품 안정성 사내 보고 2. PV (Pharmacovigilance - 약물감시) 내부 보고 3. 기준 정보 관리 | F21: Appl | I21: C&C | J21: 제조MIS서비스2팀 | K21: 정철우 | L21: 이인 | M21: 김형일 | N21: DT팀 | O21: 두상헌 | P21: 박상진 | U21: 2021 | V21: SI 개발 | W21: Javascript ES6 / JSP 2.3 | X21: jQuery 3.4.1 | Y21: Java 1.8 | Z21: 전자정부 3.9 / Spring 4.3.22 | AB21: N | AD21: MSSQL 2017 | AE21: bitbucket | AF21: Java 1.8 | AG21: Jenkins | AR21: O
A22: 제외_1 | C22: SKMU 휴폐업 중계서버 | D22: =A22 -> 제외_1 | E22: 솔루션 유지보수(고객사 직계약) | F22: Appl
A23: 제외_2 | C23: SK케미칼 휴폐업 중계서버 | D23: =A23 -> 제외_2 | E23: 솔루션 유지보수(고객사 직계약) | F23: Appl
A24: 18 | C24: 마케팅 허브 G/W | D24: =A24 -> 18 | E24: [시스템 개요] 모바일 시스템들에 접속하기 위한 허브 기능 (각 Site 에 접속하기 위한 Link 제공) [주요 기능] 1. 파마 SFE & Analysis 2. 플라즈마 SFE & Analysis 3. 모바일 MIS 4. 판촉샵 사이트 | F24: Appl | I24: C&C | J24: 제조MIS서비스2팀 | K24: 정철우 | L24: 이인 | M24: 김형일 | N24: DT팀 | O24: 두상헌 | P24: 박상진 | U24: 2020 | V24: SI 개발 | W24: Javascript ES6 / JSP 2.1 | X24: N/A | Y24: Java 1.8 | Z24: Spring 3.1.1 | AB24: Y | AC24: AWS | AD24: - | AE24: bitbucket | AF24: Java1.8 | AG24: Jenkins | AR24: O | AS24: O | AX24: O | AZ24: 서비스 Share : 비용분담 X
A25: 19 | C25: 모바일MIS | D25: =A25 -> 19 | E25: [시스템 개요] MIS 모바일 버전 | F25: Appl | I25: C&C | J25: 제조MIS서비스2팀 | K25: 정철우 | L25: 이인 | M25: 김형일 | N25: DT팀 | O25: 두상헌 | P25: 박상진 | U25: 2020 | V25: SI 개발 | W25: Javascript ES6 / JSP 2.2 | X25: jQuery 1.11.1 Angular 1.2.1 | Y25: Java 1.8 | Z25: 전자정부 2.7.0 / Spring 3.2.18 | AB25: N | AD25: - | AE25: bitbucket | AF25: Java1.8 | AG25: Jenkins | AR25: O
A26: 20 | C26: 엔티스_MIS | D26: =A26 -> 20 | E26: [시스템 개요] 엔티스 내의 회계,자금,마케팅,구매,원가,생산,물류를 관리하는 시스템 [주요기능] 1. 회계관리 2. 자금관리 3. 마케팅관리 4. 구매관리 5. 원가관리 6. 생산관리 7. 물류관리 | F26: Appl | I26: C&C | J26: 제조MIS서비스2팀 | K26: 정철우 | L26: 이인 | M26: 최창길 | N26: DT팀 | O26: 두상헌 | P26: 명진 | U26: 2006 | V26: SI 개발 | W26: VB.Net 2003 | X26: VB.Net Framework 1.1 | Y26: VB.Net 2003 | Z26: VB.Net Framework 1.1 | AB26: N | AD26: Oracle 10g | AF26: VB.Net 2003 | AG26: 수동 | AU26: O
A27: 21 | C27: 임가공포탈 | D27: =A27 -> 21 | E27: [시스템 개요] 임가공 관련한 구매 프로세스 관리 시스템 (GC, LS) [주요 기능] 1. BP (협력사) 관리 2. 구매관리, 입고관리, 납품관리 3. 게시판 관리, 결재관리 | F27: Appl | I27: C&C | J27: Plant서비스팀 | K27: 이동호 | L27: 이용재 | M27: 구본호 | N27: DT팀 | O27: 두상헌 | P27: 명진 | U27: 2020 | V27: SI 개발 | W27: Javascript ES6 / JSP 2.3 | X27: openJDK 1.8 | Y27: Java 1.8 | Z27: 전자정부 3.9 / Spring 4.3.22 | AB27: Y | AC27: AWS | AD27: MSSQL 2017 | AE27: bitbucket | AF27: Java1.8 | AG27: Jenkins | AQ27: O | AR27: O
A28: 22 | C28: 콜센터 | D28: =A28 -> 22 | E28: [시스템 개요] 대표전화로 인입된 고객의 상담정보를 관리하는 시스템. 고객의 문의내용, 이상반응, 제품불량 등의 상담정보를 등록관리 [주요 기능] 1. 고객상담 - 상담정보 등록 2. 상담이력관리 - 상담이력, 불만이력 관리 3. 재통화콜백관리 - 예약통화(재통화) 및 부재중(콜백) 전화이력 관리 4. 소비자제품관리 - 제품정보 확인 및 관리 5. FAQ 관리 - 제품별 FAQ정보 관리 | F28: Appl | I28: C&C | J28: 제조MIS서비스2팀 | K28: 정철우 | L28: 이인 | M28: 김은수 | N28: DT팀 | O28: 두상헌 | P28: 박상진 | U28: 2021 | V28: 솔루션 | W28: Javascript 1.5 / JSP 2.3 / XML 1.0 | X28: jQuery 3.1.1 | Y28: Java 1.8 / XML 1.0 | Z28: Spring 5.2 / homz 5.5.2 | AB28: N | AD28: MSSQL 2019 | AE28: - | AF28: Java1.8 | AG28: - | AR28: O
A29: 23 | C29: 파마 MIS | D29: =A29 -> 23 | E29: [시스템 개요] LS 영업 관리 시스템 [주요 기능] 1. 주문서 관리 2. 수금 관리 3. 채권 관리 / 여신관리 4. 결재 관리 (주문서, 품의서) 5. 처방관리 외 | F29: Appl | I29: C&C | J29: 제조MIS서비스2팀 | K29: 정철우 | L29: 이인 | M29: 정정배/김기정 | N29: DT팀 | O29: 두상헌 | P29: 박상진 | U29: 2015 | V29: SI 개발 | W29: C# 4.0 | X29: .Net 4.0 | Y29: C# 4.0 / 5.0 | Z29: .Net 4.0 / 4.5 | AB29: N | AD29: Oracle 19c | AE29: bitbucket | AF29: .Net 4.0 | AG29: Jenkins | AK29: Y | AR29: O
A30: 24 | C30: 파마 SFE | D30: =A30 -> 24 | E30: [시스템 개요]영업 관리 시스템 (( 활동, 현황, 분석, 일비 ), 품의&보고서, 모바일 MIS 모듈 포함) [시스템 개요] LS 영업사원 지원 관리 시스템 [주요 기능] 1. 거래처 / 고객 관리 2. Call (거래처 방문) 계획 및 실적 관리 3. 수금 관리 (카드결재) 4. 제품 설명회 / 견본품 관리 5. 부서 경비 관리 6. 지출 보고 관리 (견본품 제공, 학술대회 지원, 자문료, 강연료, 기부 외) | F30: Appl | I30: C&C | J30: 제조MIS서비스2팀 | K30: 정철우 | L30: 이인 | M30: 김형일 | N30: DT팀 | O30: 두상헌 | P30: 박상진 | U30: 2015 | V30: SI 개발 | W30: Javascript ES6 / JSP 2.2 | X30: jQuery 1.10.2 Angular 1.2.1 | Y30: Java 1.8 | Z30: 전자정부 2.7.0 / Spring 3.2.18 | AB30: N | AD30: MSSQL 2016 | AE30: bitbucket | AF30: Java1.8 | AG30: Jenkins | AJ30: Datadog | AR30: O
A31: 25 | C31: 플라즈마 SFE | D31: =A31 -> 25 | E31: [시스템 개요] 플라즈마 영업사원 지원 관리 시스템 [주요 기능] 1. 거래처 / 고객 관리 2. Call (거래처 방문) 계획 및 실적 관리 3. 수금 관리 (카드결재) 4. 제품 설명회 / 견본품 관리 5. 부서 경비 관리 6. 지출 보고 관리 (견본품 제공, 학술대회 지원, 자문료, 강연료, 기부 외) | F31: Appl | I31: C&C | J31: 제조MIS서비스2팀 | K31: 정철우 | L31: 이인 | M31: 최용진 | N31: 플라즈마 경영지원실 | O31: - | P31: 임준식 | U31: 2020 | V31: SI 개발 | W31: Javascript ES6 / JSP 2.2 | X31: jQuery 1.10.2 Angular 1.2.1 | Y31: Java 1.8 | Z31: 전자정부 2.7.0 / Spring 3.2.18 | AB31: N | AD31: MSSQL 2016 | AE31: bitbucket | AF31: Java 1.8 | AG31: Jenkins | AJ31: Datadog | AS31: O
A32: 26 | C32: 플라즈마_MIS | D32: =A32 -> 26 | E32: [시스템 개요] 플라즈마 제품 주문서 및 거래처 관리 시스템 [주요기능] 1. 주문관리 2. 매출관리 3. 채권관리 4. 거래처 관리 | F32: Appl | I32: C&C | J32: 제조MIS서비스2팀 | K32: 정철우 | L32: 이인 | M32: 최창길 | N32: 플라즈마 경영지원실 | O32: - | P32: 임준식 | U32: 2014 | V32: SI 개발 | W32: Visual Basic 6.0 | X32: N/A | Y32: Visual Basic 6.0 | Z32: N/A | AB32: N | AD32: Oracle 10g | AF32: Visual Basic 6.0 | AG32: 수동 | AS32: O
A33: 제외_3 | B33: 재무 | C33: SKMU 세금계산서 | D33: =A33 -> 제외_3 | E33: 솔루션 유지보수(고객사 직계약) | F33: Appl
A34: 27 | C34: SK케미칼 매입통합 | D34: =A34 -> 27 | E34: [시스템 개요] 국세청 신고된 전자세금계산서 수취 서비스 [주요 기능] 1. 전체 전자세금계산서 수취 | F34: Appl | I34: C&C | J34: 제조MIS서비스2팀 | K34: 정철우 | L34: 이인 | M34: 윤호정 | N34: DT팀 | O34: 두상헌 | P34: 명진 | U34: 2017 | V34: 솔루션 | W34: N/A | X34: N/A | Y34: C# 5.0 | Z34: .Net 4.5 | AB34: N | AD34: MSSQL 2019 | AE34: - | AF34: .Net 4.5 | AG34: GitLab | AQ34: O | AR34: O
A35: 28 | C35: 내부통제시스템 | D35: =A35 -> 28 | E35: [시스템 개요] 신뢰성 있는 회계 정보의 작성과 공시를 위해 회사가 갖추고 지켜야 할 재무보고에 대한 내부통제 제도이며, 재무제표 오류와 부정비리를 막기 위해 재무보고와 관련된 회사 업무를 관리 통제 하는 내부 통제 시스템 [주요 기능] 1. 스코핑 관리 2. RCM 관리 3. 모집단 관리(랜덤 SAMPLE추출 관리) 4. 증빙 관리 5. 설계/운영평가 관리 6. 위의 내용 전체 이력 관리 (운영실태평가보고서) | F35: Appl | I35: C&C | J35: 제조MIS서비스2팀 | K35: 정철우 | L35: 이인 | M35: 김소영/황영주 | N35: DT팀 | O35: 두상헌 | P35: 명진 | U35: 2021 | V35: 솔루션 | W35: C# 5.0 | X35: .Net 4.5.2 | Y35: C# 5.0 | Z35: .Net 4.5.2 | AB35: Y | AC35: AWS | AD35: MSSQL 2017 | AE35: SVN | AF35: .Net 4.5.2 | AG35: Jenkins | AJ35: Datadog | AQ35: O | AW35: O
A36: 29 | C36: 비용정산 | D36: =A36 -> 29 | E36: [시스템 개요] 법인카드, 출장비, 기타전표, 세금계산서 관련 지출결의 시스템 (GC, MU, LS) [주요 기능] 1. 법인카드/출장비 처리 2. 판매/재무 전표 처리 및 승인 관리 3. 기타 전표 관리 (SAP 기표 임시전표 관리, SFE MR 일비 관리) 4. 전자증빙 시스템 연계 기능 | F36: Appl | I36: C&C | J36: 제조MIS서비스2팀 | K36: 정철우 | L36: 이인 | M36: 김민준 | N36: DT팀 | O36: 두상헌 | P36: 명진 | U36: 2019 | V36: SI 개발 | W36: Javascript ES6 / JSP 2.3 | X36: jQuery 1.12.3 | Y36: Java 1.8 | Z36: 전자정부 3.7.0 | AB36: Y | AC36: AWS | AD36: MSSQL 2017 | AE36: bitbucket | AF36: Java 1.8 | AG36: Jenkins | AJ36: Datadog | AK36: Y | AQ36: O | AR36: O | AT36: O | AW36: O
A37: 30 | C37: 비용정산 파투아 | D37: =A37 -> 30 | E37: [시스템 개요] 카드사로부터 법인카드 데이터 수신 Agent [주요 기능] 1. 카드사 법인카드 사용 내역 I/F 2. 해당 내역을 비용정산 Sys. 과 I/F | F37: Appl | I37: C&C | J37: 제조MIS서비스2팀 | K37: 정철우 | L37: 이인 | M37: 박우선 | N37: DT팀 | O37: 두상헌 | P37: 명진 | U37: 2019 | V37: 솔루션 | W37: N/A | X37: N/A | Y37: Java 1.8 / C++ 6.0 | Z37: 자체개발 | AB37: Y | AC37: AWS | AD37: MSSQL 2017 | AE37: - | AF37: Java 1.8, .Net Framework 4.5 | AG37: sftp | AQ37: O | AR37: O | AT37: O | AW37: O | AX37: O | AZ37: 서비스 Share : 비용분담 X
A38: 31 | C38: 비용정산(전자증빙) | D38: =A38 -> 31 | E38: [시스템 개요] 회계전표에 대한 증빙 관리 시스템 [주요기능] 1. 증빙 등록 및 조회 2. 세금계산서 / 법인카드등 양식 생성 3. 모바일 증빙 등록 / 조회 | F38: Appl | I38: C&C | J38: 제조MIS서비스2팀 | K38: 정철우 | L38: 이인 | M38: 이상민 | N38: DT팀 | O38: 두상헌 | P38: 명진 | U38: 2020 | V38: 솔루션 | W38: Javascript 1.5 / JSP 2.3 / VC++ 2013 | X38: jQuery 1.11.3 / JDK 1.8 / MFC 2013 | Y38: Java 1.8 | Z38: N/A | AB38: Y | AC38: AWS | AD38: MSSQL 2017 | AE38: Git | AF38: Java 1.8, Visual Studio 2013 | AG38: - | AQ38: O | AR38: O | AT38: O | AW38: O | AX38: O | AZ38: 서비스 Share : 비용분담 X
A39: 32 | C39: 전자세금계산서 | D39: =A39 -> 32 | E39: [시스템 개요] 전자세금계산서 프로세스 관리 시스템 [주요 기능] 1. 매입/매출 세금계산서 조회 2. 세금계산서 데이터 국세청 전송 관리 3. 매출처, 매입처 기준 통계 데이터 제공 기능 | F39: Appl | I39: C&C | J39: 제조MIS서비스2팀 | K39: 정철우 | L39: 이인 | M39: 김학준/이기석 | N39: DT팀 | O39: 두상헌 | P39: 명진 | U39: 2019 | V39: 솔루션 | W39: Javascript ES2020 / JSP 2.3 | X39: jQuery 1.12 | Y39: Java 1.8 | Z39: 전자정부 4.2 | AB39: Y | AC39: AWS | AD39: MSSQL 2017 | AE39: bitbucket | AF39: Java 1.8 | AG39: Jenkins | AJ39: Datadog | AQ39: O | AR39: O | AT39: O | AU39: O | AV39: O
A40: 33 | B40: R&D | C40: MSDS 서비스 | D40: =A40 -> 33 | E40: [시스템 개요] SK케미칼(GC), 엔티스, SK케미칼 대정의 제품 MSDS문서 작성 및 유지관리 시스템 1. MSDS 작성 및 발행 2. 산업안전보건법 이행대상 관리 3. 화학물질 DB (화학물질의 국내외 규제 확인 기능) 4. 국내외 규제 daily 업데이트 | F40: Appl | I40: C&C | J40: Plant서비스팀 | K40: 이동호 | L40: 이용재 | M40: 우은정 | N40: DT팀 | O40: 두상헌 | P40: 김햇빛 | U40: 2023 | V40: 솔루션 | W40: JSP 2.3 | X40: jQuery 3.3.1 | Y40: Java 1.8 | Z40: Spring 5.1.9 | AB40: Y | AC40: AWS | AD40: MSSQL 2017 | AE40: Bitbucket | AF40: Java 1.8 | AG40: Jenkins | AQ40: O | AU40: O | AV40: O
...

Sheet 인프라 정보
H2: On-Premise/AWS | I2: DMZ/Server Farm | J2: WEB/CS/Mobile/기타
A3: No. | C3: 담당자 | H3: WEB/WAS | U3: DB | AB3: 비고
B4: 시스템명 | C4: DT팀 | D4: 통합ITO | E4: 협력 | F4: 사용여부 | G4: 개발/운영 | H4: 인프라 구분 | I4: 네트웍 구분 | J4: 플랫폼 구분 | K4: WEB | L4: WAS | M4: Hostname | N4: IP | O4: Port | P4: OS | Q4: URL | R4: 위치 | S4: SSL 도메인 | T4: 인증서 포맷 | U4: DB Hostname | V4: DB IP | W4: DB Port | X4: DB명 | Y4: DBMS | Z4: DB Size (GB, 26/1/2 조사) | AA4: DB암호화 | AB4: 비고1 | AC4: 비고2
A5: =VLOOKUP(B5,'서비스 Master'!$C$4:$D$62,2,FALSE) -> 1 | B5: HR G/W HCM G/W | C5: =VLOOKUP(B5,'서비스 Master'!$C$4:$P$62,14,FALSE) -> 김햇빛 | D5: =VLOOKUP(B5,'서비스 Master'!$C$4:$P$62,10,FALSE) -> 조래옥 | E5: =VLOOKUP(B5,'서비스 Master'!$C$4:$P$62,11,FALSE) -> 유원혁 | F5: Y | G5: 운영 | H5: On-Premise | I5: DMZ | J5: WEB | K5: IIS 10 | M5: C01VP-OCE-WEB1 | N5: 168.154.172.167 | O5: 443 | P5: Windows Server 2016 Standard | Q5: https://apigw.skchemicals.com | R5: 본사 | S5: *.skchemicals.com | T5: PFX | U5: C01VP-IDB-DB | V5: 10.247.243.23 | W5: 51433 | X5: EHRGW | Y5: MSSQL 2019 | Z5: 177.2 | AA5: TDE | AB5: 세일즈포스 OCE 연동 Gateway | AC5: 연결 DB정보 확인 필요 : C01VP-IDB-DB1(A), C01VP-IDB-DB2(S)
A6: =VLOOKUP(B6,'서비스 Master'!$C$4:$D$62,2,FALSE) -> 1 | B6: HR G/W HCM G/W | C6: =VLOOKUP(B6,'서비스 Master'!$C$4:$P$62,14,FALSE) -> 김햇빛 | D6: =VLOOKUP(B6,'서비스 Master'!$C$4:$P$62,10,FALSE) -> 조래옥 | E6: =VLOOKUP(B6,'서비스 Master'!$C$4:$P$62,11,FALSE) -> 유원혁 | F6: Y | G6: 개발 | H6: On-Premise | I6: Server Farm | J6: WEB | K6: IIS 10 | M6: C01VD-OCE-WEB1 | N6: 10.247.246.13 | O6: 443 | P6: Windows Server 2016 Standard | Q6: https://dev-apigw.skchemicals.com | R6: 본사 | S6: *.skchemicals.com | T6: PFX | U6: C01VD-IDB-DB1 | V6: 10.247.246.27 | W6: 51433 | X6: EHRGW | Y6: MSSQL 2019 | Z6: 0 | AA6: TDE
A7: =VLOOKUP(B7,'서비스 Master'!$C$4:$D$62,2,FALSE) -> 2 | B7: MDM 시스템 | C7: =VLOOKUP(B7,'서비스 Master'!$C$4:$P$62,14,FALSE) -> 유현상 | D7: =VLOOKUP(B7,'서비스 Master'!$C$4:$P$62,10,FALSE) -> 이용재 | E7: =VLOOKUP(B7,'서비스 Master'!$C$4:$P$62,11,FALSE) -> 민준홍 | F7: Y | G7: 운영 | H7: AWS | J7: WEB | L7: Tomcat 9.0.91 | M7: C31CP-MDM-AP1 | N7: 10.247.220.14 | O7: 3389 | P7: Windows Server 2019 Standard | Q7: https://mdm.skchemicals.com/ | S7: *.skchemicals.com | T7: JKS | U7: C31CP-MDIS-DB2 | V7: 10.247.220.149 | W7: 51433 | X7: MDM | Y7: MSSQL 2017 | Z7: 63.8
A8: =VLOOKUP(B8,'서비스 Master'!$C$4:$D$62,2,FALSE) -> 2 | B8: MDM 시스템 | C8: =VLOOKUP(B8,'서비스 Master'!$C$4:$P$62,14,FALSE) -> 유현상 | D8: =VLOOKUP(B8,'서비스 Master'!$C$4:$P$62,10,FALSE) -> 이용재 | E8: =VLOOKUP(B8,'서비스 Master'!$C$4:$P$62,11,FALSE) -> 민준홍 | F8: Y | G8: 운영 | H8: AWS | J8: WEB | L8: Tomcat 9.0.91 | M8: C31CP-MDM-AP2 | N8: 10.247.220.114 | O8: 3389 | P8: Windows Server 2019 Standard | Q8: https://mdm.skchemicals.com/ | U8: C31CP-MDIS-DB2 | V8: 10.247.220.149 | W8: 51433 | X8: MDM | Y8: MSSQL 2017 | Z8: 63.8 | AC8: SSL 인증서 설치 여부 확인 필요
A9: =VLOOKUP(B9,'서비스 Master'!$C$4:$D$62,2,FALSE) -> 2 | B9: MDM 시스템 | C9: =VLOOKUP(B9,'서비스 Master'!$C$4:$P$62,14,FALSE) -> 유현상 | D9: =VLOOKUP(B9,'서비스 Master'!$C$4:$P$62,10,FALSE) -> 이용재 | E9: =VLOOKUP(B9,'서비스 Master'!$C$4:$P$62,11,FALSE) -> 민준홍 | F9: Y | G9: 운영 | H9: AWS | J9: Mobile | K9: Apache 2.4.51 | L9: Tomcat 9.0.91 | M9: C31CP-MDM-AP3 | N9: 10.247.220.16 | O9: 3389 | P9: Windows Server 2019 Standard | Q9: https://m-mdm.skchemicals.com/ | U9: C31CP-MDIS-DB2 | V9: 10.247.220.149 | W9: 51433 | X9: MDM | Y9: MSSQL 2017 | Z9: 63.8 | AB9: MDM 모바일 서비스 제공 | AC9: SSL 인증서 설치 여부 확인 필요
A10: =VLOOKUP(B10,'서비스 Master'!$C$4:$D$62,2,FALSE) -> 2 | B10: MDM 시스템 | C10: =VLOOKUP(B10,'서비스 Master'!$C$4:$P$62,14,FALSE) -> 유현상 | D10: =VLOOKUP(B10,'서비스 Master'!$C$4:$P$62,10,FALSE) -> 이용재 | E10: =VLOOKUP(B10,'서비스 Master'!$C$4:$P$62,11,FALSE) -> 민준홍 | F10: Y | G10: 개발 | H10: AWS | J10: WEB | L10: Tomcat 9.0.91 | M10: C31CD-MDM-AP1 | N10: 10.247.216.14 | O10: 53389 | P10: Windows Server 2019 Standard | Q10: https://mdm-dev.skchemicals.com/ | S10: *.skchemicals.com | T10: JKS | U10: C31CD-MDIS-DB1 | V10: 10.247.216.152 | W10: 51433 | X10: MDM_DEV | Y10: MSSQL 2017 | Z10: 41.2
A11: =VLOOKUP(B11,'서비스 Master'!$C$4:$D$62,2,FALSE) -> 5 | B11: RPA | C11: =VLOOKUP(B11,'서비스 Master'!$C$4:$P$62,14,FALSE) -> 김햇빛 | D11: =VLOOKUP(B11,'서비스 Master'!$C$4:$P$62,10,FALSE) -> 이인 | E11: =VLOOKUP(B11,'서비스 Master'!$C$4:$P$62,11,FALSE) -> 김건휘 | F11: Y | G11: 운영 | H11: AWS | J11: 기타 | M11: C33CP-RPA-AP1 | N11: 10.247.222.15 | P11: Windows Server 2019 Datacenter (64-bit) | Q11: https://rpa.skchemicals.com/ | S11: *.skchemicals.com | T11: PEM | U11: C31CP-MDIS-DB2 | V11: 10.247.220.149 | W11: 51433 | X11: RPA | Y11: MSSQL 2017 | Z11: 8.1 | AB11: 운영(통합 EC2 DB)
A12: =VLOOKUP(B12,'서비스 Master'!$C$4:$D$62,2,FALSE) -> 5 | B12: RPA | C12: =VLOOKUP(B12,'서비스 Master'!$C$4:$P$62,14,FALSE) -> 김햇빛 | D12: =VLOOKUP(B12,'서비스 Master'!$C$4:$P$62,10,FALSE) -> 이인 | E12: =VLOOKUP(B12,'서비스 Master'!$C$4:$P$62,11,FALSE) -> 김건휘 | F12: Y | G12: 개발 | H12: AWS | J12: 기타 | M12: C33CD-RPA-AP1 | N12: 10.247.217.15 | P12: Windows Server 2019 Datacenter (64-bit) | Q12: https://rpa-cd.skchemicals.com/ | S12: *.skchemicals.com | T12: PEM | U12: C31CD-MDIS-DB1 | V12: 10.247.216.152 | W12: 51433 | X12: RPA | Y12: MSSQL 2017 | Z12: 7.7 | AB12: 개발
A13: =VLOOKUP(B13,'서비스 Master'!$C$4:$D$62,2,FALSE) -> 7 | B13: 구)e-HR | C13: =VLOOKUP(B13,'서비스 Master'!$C$4:$P$62,14,FALSE) -> 김햇빛 | D13: =VLOOKUP(B13,'서비스 Master'!$C$4:$P$62,10,FALSE) -> 조래옥 | E13: =VLOOKUP(B13,'서비스 Master'!$C$4:$P$62,11,FALSE) -> 정정배/김기정 | F13: Y | G13: 운영 | H13: On-Premise | J13: WEB | K13: Httpd.exe (resin 3.0) | L13: Httpd.exe (resin 3.0) | M13: C01VP-EHR-AP1 | N13: 10.247.241.58 | O13: 80 | P13: Windows Server 2003 Standard (32-bit) | Q13: http://ehris.skchemicals.com | R13: 본사 | S13: *.skchemicals.com | T13: 비대상 | U13: E01VP-HRMIS-DB1 | V13: 10.247.241.151 | W13: 1521 | Y13: Oracle 10g | Z13: 22.5 | AB13: 5/11 or 5/18 10.247.243.53로 변경(대덕->판교로 이전) | AC13: 정보 확인 필요
A14: =VLOOKUP(B14,'서비스 Master'!$C$4:$D$62,2,FALSE) -> 8 | B14: 데이터레이크 | C14: =VLOOKUP(B14,'서비스 Master'!$C$4:$P$62,14,FALSE) -> 민석홍 | D14: =VLOOKUP(B14,'서비스 Master'!$C$4:$P$62,10,FALSE) -> 조래옥 | E14: =VLOOKUP(B14,'서비스 Master'!$C$4:$P$62,11,FALSE) -> 경규민 | F14: Y | G14: 운영 | H14: AWS | J14: WEB | S14: *.skchemicals.com | T14: 비대상 | AB14: 저장공간은 AWS S3 | AC14: 정보 확인 필요
A15: =VLOOKUP(B15,'서비스 Master'!$C$4:$D$62,2,FALSE) -> #N/A | B15: 데이터포털_태블로 | C15: 민석홍 | E15: 임정섭 | F15: Y | G15: 운영 | H15: On-Premise | I15: Server Farm | K15: Apache | M15: C01VP-TBL-AP1 | N15: 10.247.241.118 | O15: 443 | P15: Windows Server 2019 Standard | R15: 본사 | U15: C01VP-TBL-AP1 | V15: 10.247.241.118 | Y15: PostgreSQL | AB15: 데이터포털에서 연동하는 정보 태블로 삭제 필요, AP/DB서버 | AC15: Non-ITO
A16: =VLOOKUP(B16,'서비스 Master'!$C$4:$D$62,2,FALSE) -> 9 | B16: 데이터포털 | C16: =VLOOKUP(B16,'서비스 Master'!$C$4:$P$62,14,FALSE) -> 민석홍 | D16: =VLOOKUP(B16,'서비스 Master'!$C$4:$P$62,10,FALSE) -> 조래옥 | E16: =VLOOKUP(B16,'서비스 Master'!$C$4:$P$62,11,FALSE) -> 구본호 | F16: Y | G16: 운영 | H16: AWS | J16: WEB | L16: nestjs 9.4.0/express 4.18.2 | M16: C31CP-DATA-WEB1 | N16: 10.247.220.166 | O16: 55522 | P16: Amazon Linux 2 | Q16: https://dtpl.skchemicals.com/main | S16: *.skchemicals.com | T16: PFX | U16: C31CP-DATA-DB1 | V16: 10.247.222.164 | W16: 27017 | X16: dp | Y16: MongoDB 5.0.24 | Z16: 9.8 | AB16: AWS EC2
A17: =VLOOKUP(B17,'서비스 Master'!$C$4:$D$62,2,FALSE) -> 9 | B17: 데이터포털 | C17: =VLOOKUP(B17,'서비스 Master'!$C$4:$P$62,14,FALSE) -> 민석홍 | D17: =VLOOKUP(B17,'서비스 Master'!$C$4:$P$62,10,FALSE) -> 조래옥 | E17: =VLOOKUP(B17,'서비스 Master'!$C$4:$P$62,11,FALSE) -> 구본호 | F17: Y | G17: 개발 | H17: AWS | J17: WEB | L17: nestjs 9.4.0/express 4.18.2 | M17: C31CD-DATA-WEB1 | N17: 10.247.216.170 | O17: 55522 | P17: Amazon Linux 2 | Q17: https://dtpl-dev.skchemicals.com/sk-login | S17: *.skchemicals.com | T17: PFX | U17: C31CD-DATA-DB1 | V17: 10.247.217.168 | W17: 27017 | X17: dp | Y17: MongoDB 5.0.24 | Z17: 10.4 | AB17: AWS EC2
A18: =VLOOKUP(B18,'서비스 Master'!$C$4:$D$62,2,FALSE) -> 0 | B18: 표준관리시스템 | C18: =VLOOKUP(B18,'서비스 Master'!$C$4:$P$62,14,FALSE) -> 민석홍 | D18: =VLOOKUP(B18,'서비스 Master'!$C$4:$P$62,10,FALSE) -> 조래옥 | E18: =VLOOKUP(B18,'서비스 Master'!$C$4:$P$62,11,FALSE) -> 구본호 | F18: Y | G18: 운영 | H18: On-Premise | J18: WEB | L18: Tomcat 9.0.70 | M18: C01VP-DLM-WAS1 | N18: 10.247.241.96 | O18: 55522 | P18: Ubuntu 22.04.4 LTS | Q18: https://meta.skchemicals.com/dataware/login.action | R18: 본사 | S18: *.skchemicals.com | T18: PFX | U18: C01VP-DLM-DB1 | V18: 10.247.243.52 | W18: 55432 | X18: dataware | Y18: PostgreSQL 17 | Z18: 14 | AB18: 데이터포털 - 표준관리시스템(META)
A19: =VLOOKUP(B19,'서비스 Master'!$C$4:$D$62,2,FALSE) -> 0 | B19: 표준관리시스템 | C19: =VLOOKUP(B19,'서비스 Master'!$C$4:$P$62,14,FALSE) -> 민석홍 | D19: =VLOOKUP(B19,'서비스 Master'!$C$4:$P$62,10,FALSE) -> 조래옥 | E19: =VLOOKUP(B19,'서비스 Master'!$C$4:$P$62,11,FALSE) -> 구본호 | F19: Y | G19: 개발 | H19: On-Premise | J19: WEB | L19: Tomcat 9.0.70 | M19: C01VD-DLM-WAS1 | N19: 10.247.246.72 | O19: 443 | P19: Ubuntu 22.04.4 LTS | Q19: https://meta-dev.skchemicals.com/dataware/login.action | R19: 본사 | S19: *.skchemicals.com | T19: PFX | U19: C01VD-DLM-DB1 | V19: 10.247.246.73 | W19: 55432 | X19: dataware | Y19: PostgreSQL 17 | Z19: 11.8 | AB19: 데이터포털 - 표준관리시스템(META)
A20: =VLOOKUP(B20,'서비스 Master'!$C$4:$D$62,2,FALSE) -> 11 | B20: 법무포탈 | C20: =VLOOKUP(B20,'서비스 Master'!$C$4:$P$62,14,FALSE) -> 김햇빛 | D20: =VLOOKUP(B20,'서비스 Master'!$C$4:$P$62,10,FALSE) -> 조래옥 | E20: =VLOOKUP(B20,'서비스 Master'!$C$4:$P$62,11,FALSE) -> 김아현 | F20: Y | G20: 운영 | H20: AWS | J20: WEB | L20: Tomcat 9.0.27 | M20: C31CP-LPO-WEB1 | N20: 10.247.220.22 | O20: 80 | P20: Windows 10 Enterprise | Q20: https://legal.skcemicals.com | S20: *.skchemicals.com | T20: PEM | U20: C31CP-MDIS-DB2 | V20: 10.247.220.149 | W20: 51433 | X20: sk_chemicals_elms | Y20: MSSQL 2017 | Z20: 127.9 | AB20: 통합 EC2 DB | AC20: DB Hostname 확인필요 : C31CP-MDIS-DB1
A21: =VLOOKUP(B21,'서비스 Master'!$C$4:$D$62,2,FALSE) -> 11 | B21: 법무포탈 | C21: =VLOOKUP(B21,'서비스 Master'!$C$4:$P$62,14,FALSE) -> 김햇빛 | D21: =VLOOKUP(B21,'서비스 Master'!$C$4:$P$62,10,FALSE) -> 조래옥 | E21: =VLOOKUP(B21,'서비스 Master'!$C$4:$P$62,11,FALSE) -> 김아현 | F21: Y | G21: 개발 | H21: AWS | J21: WEB | L21: Tomcat 9.0.27 | M21: C31CD-LPO-WEB1 | N21: 10.247.216.22 | O21: 80 | P21: Windows 10 Enterprise | Q21: https://dev-legal.skchemicals.com | S21: *.skchemicals.com | T21: PEM | U21: C31CD-MDIS-DB1 | V21: 10.247.216.152 | W21: 51433 | X21: sk_chemicals_elms | Y21: MSSQL 2017 | Z21: 0.2 | AB21: 통합 EC2 DB
A22: =VLOOKUP(B22,'서비스 Master'!$C$4:$D$62,2,FALSE) -> 12 | B22: 스마트오피스 서비스 | C22: =VLOOKUP(B22,'서비스 Master'!$C$4:$P$62,14,FALSE) -> 김햇빛 | D22: =VLOOKUP(B22,'서비스 Master'!$C$4:$P$62,10,FALSE) -> 조래옥 | E22: =VLOOKUP(B22,'서비스 Master'!$C$4:$P$62,11,FALSE) -> 변영운 | F22: Y | G22: 운영 | H22: AWS | J22: WEB | K22: Apache 2.4.52 | L22: Tomcat 8.5.75 | M22: C33CP-FRC-AP1 | N22: 10.247.220.117 | O22: 55522 | P22: Amazon Linux 2 | Q22: https://smartoffice.skchemicals.com | S22: *.skchemicals.com | T22: PEM | U22: C31CP-SO-DB1 | V22: skch-backbone-prod-rds-so-db01.chcdnqliroxp.ap-northeast-2.rds.amazonaws.com | W22: 3306 | X22: smartoffice | Y22: MariaDB 10.6.18 | Z22: 21 | AB22: 안면인식 솔루션 SAFR 플랫폼 : 해외 솔루션으로 업그레이드 불가 ‘24년 보안진단 시에도 예외 처리 요청
A23: =VLOOKUP(B23,'서비스 Master'!$C$4:$D$62,2,FALSE) -> 12 | B23: 스마트오피스 서비스 | C23: =VLOOKUP(B23,'서비스 Master'!$C$4:$P$62,14,FALSE) -> 김햇빛 | D23: =VLOOKUP(B23,'서비스 Master'!$C$4:$P$62,10,FALSE) -> 조래옥 | E23: =VLOOKUP(B23,'서비스 Master'!$C$4:$P$62,11,FALSE) -> 변영운 | F23: Y | G23: 운영 | H23: AWS | J23: WEB | K23: Apache 2.4.57 | L23: Tomcat 9.0.109 | M23: C33CP-SO-AP1 | N23: 10.247.220.4 | O23: 55522 | P23: Amazon Linux 2 | Q23: https://smartoffice.skchemicals.com | S23: *.skchemicals.com | T23: PEM | U23: C31CP-SO-DB1 | V23: skch-backbone-prod-rds-so-db01.chcdnqliroxp.ap-northeast-2.rds.amazonaws.com | W23: 3306 | X23: smartoffice | Y23: MariaDB 10.6.18 | Z23: 21
A24: =VLOOKUP(B24,'서비스 Master'!$C$4:$D$62,2,FALSE) -> 12 | B24: 스마트오피스 서비스 | C24: =VLOOKUP(B24,'서비스 Master'!$C$4:$P$62,14,FALSE) -> 김햇빛 | D24: =VLOOKUP(B24,'서비스 Master'!$C$4:$P$62,10,FALSE) -> 조래옥 | E24: =VLOOKUP(B24,'서비스 Master'!$C$4:$P$62,11,FALSE) -> 변영운 | F24: Y | G24: 운영 | H24: AWS | J24: WEB | K24: Apache 2.4.57 | L24: Tomcat 9.0.109 | M24: C33CP-SO-AP2 | N24: 10.247.222.82 | O24: 55522 | P24: Amazon Linux 2 | Q24: https://smartoffice.skchemicals.com | S24: *.skchemicals.com | T24: PEM | U24: C31CP-SO-DB1 | V24: skch-backbone-prod-rds-so-db01.chcdnqliroxp.ap-northeast-2.rds.amazonaws.com | W24: 3306 | X24: smartoffice | Y24: MariaDB 10.6.18 | Z24: 21
A25: =VLOOKUP(B25,'서비스 Master'!$C$4:$D$62,2,FALSE) -> 12 | B25: 스마트오피스 서비스 | C25: =VLOOKUP(B25,'서비스 Master'!$C$4:$P$62,14,FALSE) -> 김햇빛 | D25: =VLOOKUP(B25,'서비스 Master'!$C$4:$P$62,10,FALSE) -> 조래옥 | E25: =VLOOKUP(B25,'서비스 Master'!$C$4:$P$62,11,FALSE) -> 변영운 | F25: Y | G25: 개발 | H25: AWS | J25: WEB | L25: Tomcat 8.5.87 | M25: C33CD-SO-AP1 | N25: 10.247.216.85 | O25: 55522 | P25: Amazon Linux 2 | Q25: https://smartoffice-test.skchemicals.com | S25: *.skchemicals.com | T25: PEM | U25: C31CD-SO-DB1 | V25: skch-backbone-dev-rds-so-db01.cji5alpv69zu.ap-northeast-2.rds.amazonaws.com | W25: 3306 | X25: smartoffice | Y25: MariaDB 10.6.18 | Z25: 33.7
A26: =VLOOKUP(B26,'서비스 Master'!$C$4:$D$62,2,FALSE) -> 13 | B26: ESG Data HUB | C26: =VLOOKUP(B26,'서비스 Master'!$C$4:$P$62,14,FALSE) -> 김햇빛 | D26: =VLOOKUP(B26,'서비스 Master'!$C$4:$P$62,10,FALSE) -> 조래옥 | E26: =VLOOKUP(B26,'서비스 Master'!$C$4:$P$62,11,FALSE) -> 한준호 | F26: Y | G26: 운영 | H26: AWS | J26: WEB | L26: Tomcat 9.0.86 | M26: C33CP-EHUB-WEB1 | N26: 10.247.220.31 | O26: 80/8090 | P26: Amazon Linux 2 | Q26: https://edh.skchemicals.com | S26: *.skchemicals.com | T26: PEM | U26: C31CP-MDIS-DB2 | V26: 10.247.220.149 | W26: 51433 | X26: EDH | Y26: MSSQL 2017 | Z26: 1.4 | AB26: 통합 EC2 DB
A27: =VLOOKUP(B27,'서비스 Master'!$C$4:$D$62,2,FALSE) -> 13 | B27: ESG Data HUB | C27: =VLOOKUP(B27,'서비스 Master'!$C$4:$P$62,14,FALSE) -> 김햇빛 | D27: =VLOOKUP(B27,'서비스 Master'!$C$4:$P$62,10,FALSE) -> 조래옥 | E27: =VLOOKUP(B27,'서비스 Master'!$C$4:$P$62,11,FALSE) -> 한준호 | F27: Y | G27: 운영 | H27: AWS | J27: WEB | L27: Tomcat 9.0.86 | M27: C33CP-EHUB-WEB2 | N27: 10.247.222.97 | O27: 80/8090 | P27: Amazon Linux 2 | Q27: https://edh.skchemicals.com | S27: *.skchemicals.com | T27: PEM | U27: C31CP-MDIS-DB2 | V27: 10.247.220.149 | W27: 51433 | X27: EDH | Y27: MSSQL 2017 | Z27: 1.4 | AB27: 통합 EC2 DB
A28: =VLOOKUP(B28,'서비스 Master'!$C$4:$D$62,2,FALSE) -> 13 | B28: ESG Data HUB | C28: =VLOOKUP(B28,'서비스 Master'!$C$4:$P$62,14,FALSE) -> 김햇빛 | D28: =VLOOKUP(B28,'서비스 Master'!$C$4:$P$62,10,FALSE) -> 조래옥 | E28: =VLOOKUP(B28,'서비스 Master'!$C$4:$P$62,11,FALSE) -> 한준호 | F28: Y | G28: 개발 | H28: AWS | J28: WEB | L28: Tomcat 9.0.86 | M28: C33CD-EHUB-WEB1.SKYNET.HELP | N28: 10.247.216.84 | O28: 80/8090 | P28: Amazon Linux 2 | Q28: https://edh-dev.skchemicals.com | S28: *.skchemicals.com | T28: PEM | U28: C31CD-MDIS-DB1 | V28: 10.247.216.152 | W28: 51433 | X28: EDH | Y28: MSSQL 2017 | Z28: 0.5 | AB28: 통합 EC2 DB
A29: =VLOOKUP(B29,'서비스 Master'!$C$4:$D$62,2,FALSE) -> 14 | B29: 톡톡 스마트오피스 앱 | C29: =VLOOKUP(B29,'서비스 Master'!$C$4:$P$62,14,FALSE) -> 김햇빛 | D29: =VLOOKUP(B29,'서비스 Master'!$C$4:$P$62,10,FALSE) -> 조래옥 | E29: =VLOOKUP(B29,'서비스 Master'!$C$4:$P$62,11,FALSE) -> 정상률 | F29: Y | J29: Mobile | T29: 비대상
A30: =VLOOKUP(B30,'서비스 Master'!$C$4:$D$62,2,FALSE) -> 15 | B30: CRM (S.Square) | C30: =VLOOKUP(B30,'서비스 Master'!$C$4:$P$62,14,FALSE) -> 김햇빛 | D30: =VLOOKUP(B30,'서비스 Master'!$C$4:$P$62,10,FALSE) -> 이인 | E30: =VLOOKUP(B30,'서비스 Master'!$C$4:$P$62,11,FALSE) -> 박도현 | F30: Y | G30: 운영 | H30: AWS | J30: WEB | K30: IIS 10 | M30: C33CP-CRM-WEB1 | N30: 10.247.222.11 | O30: 443 | P30: Windows Server 2019 Standard | Q30: https://gccrm.skchemicals.com | S30: *.skchemicals.com | T30: 비대상 | U30: C31CP-MDIS-DB2 | V30: 10.247.220.149 | W30: 51433 | X30: Connected2ND | Y30: MSSQL 2017 | Z30: 7.4 | AB30: 운영(통합 EC2 DB) | AC30: 25년 2분기 이후 통합ITO 계약 종료
A31: =VLOOKUP(B31,'서비스 Master'!$C$4:$D$62,2,FALSE) -> 15 | B31: CRM (S.Square) | C31: =VLOOKUP(B31,'서비스 Master'!$C$4:$P$62,14,FALSE) -> 김햇빛 | D31: =VLOOKUP(B31,'서비스 Master'!$C$4:$P$62,10,FALSE) -> 이인 | E31: =VLOOKUP(B31,'서비스 Master'!$C$4:$P$62,11,FALSE) -> 박도현 | F31: Y | G31: 개발 | H31: AWS | J31: WEB | K31: IIS 10 | M31: C33CD-CRM-WEB1 | N31: 10.247.217.11 | O31: 443 | P31: Windows Server 2019 Standard | Q31: https://gccrm-dev.skchemicals.com | S31: *.skchemicals.com | T31: 비대상 | U31: C31CD-MDIS-DB1 | V31: 10.247.216.152 | W31: 51433 | X31: Connected2ND | Y31: MSSQL 2017 | Z31: 5.6 | AB31: 개발(통합 EC2 DB) | AC31: 25년 2분기 이후 통합ITO 계약 종료
A32: =VLOOKUP(B32,'서비스 Master'!$C$4:$D$62,2,FALSE) -> 16 | B32: EOS G/W | C32: =VLOOKUP(B32,'서비스 Master'!$C$4:$P$62,14,FALSE) -> 박상진 | D32: =VLOOKUP(B32,'서비스 Master'!$C$4:$P$62,10,FALSE) -> 이인 | E32: =VLOOKUP(B32,'서비스 Master'!$C$4:$P$62,11,FALSE) -> 김기정 | F32: Y | G32: 운영 | H32: On-Premise | I32: DMZ | J32: WEB | K32: IIS 10 | M32: C04VP-OCE-WEB1 | N32: 10.247.13.168 | O32: 443 | P32: Windows Server 2016 Standard | Q32: https://eosgw.skchemicals.com | R32: 청주 | S32: *.skchemicals.com | T32: PFX | AB32: EOS <-> LS-MIS, 인터페이스 GW (DB는 LS-MIS), 웹서비스를 통해 I/F처리
A33: =VLOOKUP(B33,'서비스 Master'!$C$4:$D$62,2,FALSE) -> 16 | B33: EOS G/W | C33: =VLOOKUP(B33,'서비스 Master'!$C$4:$P$62,14,FALSE) -> 박상진 | D33: =VLOOKUP(B33,'서비스 Master'!$C$4:$P$62,10,FALSE) -> 이인 | E33: =VLOOKUP(B33,'서비스 Master'!$C$4:$P$62,11,FALSE) -> 김기정 | F33: Y | G33: 개발 | H33: On-Premise | I33: Server Farm | J33: WEB | K33: IIS 10 | M33: C04VD-OCE-WEB1 | N33: 10.247.26.61 | O33: 443 | P33: Windows Server 2016 Standard | Q33: https://eosgw-dev.skchemicals.com | R33: 청주 | S33: *.skchemicals.com | T33: PFX | AB33: 개발서버 (환경은 운영과 동일)
A34: =VLOOKUP(B34,'서비스 Master'!$C$4:$D$62,2,FALSE) -> 17 | B34: SIRS | C34: =VLOOKUP(B34,'서비스 Master'!$C$4:$P$62,14,FALSE) -> 박상진 | D34: =VLOOKUP(B34,'서비스 Master'!$C$4:$P$62,10,FALSE) -> 이인 | E34: =VLOOKUP(B34,'서비스 Master'!$C$4:$P$62,11,FALSE) -> 김형일 | F34: Y | G34: 운영 | H34: On-Premise | I34: Server Farm | J34: WEB | L34: Tomcat 9.0.43 | M34: C04VP-SIRS-AP1 | N34: 10.247.15.123 | O34: 53389 | P34: Windows Server 2016 Standard | Q34: https://sirs.skchemicals.com | R34: 청주 | S34: *.skchemicals.com | T34: JKS | U34: C04VP-MDIS-DB2 | V34: 10.247.15.112 | W34: 51433 | X34: SKSIRS | Y34: MSSQL 2017 | Z34: 0.3 | AB34: 이상 사례(안정성보고,SIRS)
A35: =VLOOKUP(B35,'서비스 Master'!$C$4:$D$62,2,FALSE) -> 17 | B35: SIRS | C35: =VLOOKUP(B35,'서비스 Master'!$C$4:$P$62,14,FALSE) -> 박상진 | D35: =VLOOKUP(B35,'서비스 Master'!$C$4:$P$62,10,FALSE) -> 이인 | E35: =VLOOKUP(B35,'서비스 Master'!$C$4:$P$62,11,FALSE) -> 김형일 | F35: Y | G35: 개발 | H35: On-Premise | I35: Server Farm | J35: WEB | L35: Tomcat 9.0.43 | M35: C04VD-SIRS-AP1 | N35: 10.247.26.60 | O35: 443 | P35: Windows Server 2016 Standard | Q35: https://sirs-dev.skchemicals.com | R35: 청주 | S35: *.skchemicals.com | T35: JKS | U35: C04VD-MDIS-DB1 | V35: 10.247.26.100 | W35: 51433 | X35: SKSIRS | Y35: MSSQL 2017 | Z35: 0.1 | AB35: 이상 사례(안정성보고,SIRS)
A36: =VLOOKUP(B36,'서비스 Master'!$C$4:$D$62,2,FALSE) -> 18 | B36: 마케팅 허브 G/W | C36: =VLOOKUP(B36,'서비스 Master'!$C$4:$P$62,14,FALSE) -> 박상진 | D36: =VLOOKUP(B36,'서비스 Master'!$C$4:$P$62,10,FALSE) -> 이인 | E36: =VLOOKUP(B36,'서비스 Master'!$C$4:$P$62,11,FALSE) -> 김형일 | F36: N | G36: 운영 | H36: On-Premise | I36: DMZ | L36: Tomcat 8.5.87 | M36: SKCHEM-LSMTGW | N36: 168.154.172.140 | O36: 3389 | P36: Windows Server 2008 R2 (64-bit) | Q36: https://lsmarketinghub.skchemicals.com | AB36: 사용안하는 서버( 서버EOS로 C31CP-SFE-WEB1로 이관됨)
A37: =VLOOKUP(B37,'서비스 Master'!$C$4:$D$62,2,FALSE) -> 18 | B37: 마케팅 허브 G/W | C37: =VLOOKUP(B37,'서비스 Master'!$C$4:$P$62,14,FALSE) -> 박상진 | D37: =VLOOKUP(B37,'서비스 Master'!$C$4:$P$62,10,FALSE) -> 이인 | E37: =VLOOKUP(B37,'서비스 Master'!$C$4:$P$62,11,FALSE) -> 김형일 | F37: Y | G37: 운영 | H37: AWS | J37: WEB | L37: Tomcat 9.0.97 | M37: C31CP-SFE-WEB1 | N37: 10.247.220.87 | O37: 53389 | P37: Windows Server 2022 Datacenter | Q37: https://lsmarketinghub.skchemicals.com | S37: *.skchemicals.com | T37: JKS | AB37: 운영 Relay Server (해당서버 경유하여 LSFE, BSFE, PSFE 이외 사이트 연결 해주는 역할) , DB 서버 없음
A38: =VLOOKUP(B38,'서비스 Master'!$C$4:$D$62,2,FALSE) -> 18 | B38: 마케팅 허브 G/W | C38: =VLOOKUP(B38,'서비스 Master'!$C$4:$P$62,14,FALSE) -> 박상진 | D38: =VLOOKUP(B38,'서비스 Master'!$C$4:$P$62,10,FALSE) -> 이인 | E38: =VLOOKUP(B38,'서비스 Master'!$C$4:$P$62,11,FALSE) -> 김형일 | F38: Y | G38: 개발 | H38: AWS | J38: WEB | L38: Tomcat 9.0.97 | M38: C31CD-SFE-WEB1 | N38: 10.247.216.94 | O38: 53389 | P38: Windows Server 2022 Datacenter | Q38: https://dev-lsmarketinghub.skchemicals.com | S38: *.skchemicals.com | T38: JKS | AB38: 운영 Relay Server (해당서버 경유하여 LSFE, BSFE, PSFE 이외 사이트 연결 해주는 역할) , DB 서버 없음
A39: =VLOOKUP(B39,'서비스 Master'!$C$4:$D$62,2,FALSE) -> 19 | B39: 모바일MIS | C39: =VLOOKUP(B39,'서비스 Master'!$C$4:$P$62,14,FALSE) -> 박상진 | D39: =VLOOKUP(B39,'서비스 Master'!$C$4:$P$62,10,FALSE) -> 이인 | E39: =VLOOKUP(B39,'서비스 Master'!$C$4:$P$62,11,FALSE) -> 김형일 | F39: Y | G39: 운영 | H39: On-Premise | I39: Server Farm | J39: Mobile | L39: Tomcat 7.0.104 | M39: C04VP-SFE-WAS2 | N39: 10.247.15.43 | O39: 53389 | P39: Windows Server 2016 Standard | Q39: https://sfe.skchemicals.com | R39: 청주 | S39: *.skchemicals.com | T39: JKS | AB39: 비대상,MMIS는 SFE에 종속된 시스템으로 DB는 별도 없으며, MIS와 SOAP 통신
A40: =VLOOKUP(B40,'서비스 Master'!$C$4:$D$62,2,FALSE) -> 19 | B40: 모바일MIS | C40: =VLOOKUP(B40,'서비스 Master'!$C$4:$P$62,14,FALSE) -> 박상진 | D40: =VLOOKUP(B40,'서비스 Master'!$C$4:$P$62,10,FALSE) -> 이인 | E40: =VLOOKUP(B40,'서비스 Master'!$C$4:$P$62,11,FALSE) -> 김형일 | F40: Y | G40: 개발 | H40: On-Premise | I40: Server Farm | J40: Mobile | L40: Tomcat 7.0.67 | M40: C04VD-SFE-WAS2 | N40: 10.247.26.56 | O40: 443 | P40: Windows Server 2016 Standard | Q40: https://dev-sfe.skchemicals.com | R40: 청주 | S40: *.skchemicals.com | T40: JKS | AB40: 비대상,MMIS는 SFE에 종속된 시스템으로 DB는 별도 없으며, MIS와 SOAP 통신
A41: =VLOOKUP(B41,'서비스 Master'!$C$4:$D$62,2,FALSE) -> 20 | B41: 엔티스_MIS | C41: =VLOOKUP(B41,'서비스 Master'!$C$4:$P$62,14,FALSE) -> 명진 | D41: =VLOOKUP(B41,'서비스 Master'!$C$4:$P$62,10,FALSE) -> 이인 | E41: =VLOOKUP(B41,'서비스 Master'!$C$4:$P$62,11,FALSE) -> 최창길 | F41: Y | G41: 운영 | H41: On-Premise | J41: CS | M41: E01VP-MIS-AP1 | N41: 10.247.241.229​ | P41: Windows Server 2003 R2 | R41: 본사 | S41: *.skchemicals.com | T41: 비대상 | U41: E01YP-HRMIS-DB1 | V41: 10.247.241.151 | W41: 1521 | X41: SKCHEM | Y41: Oracle 10g | Z41: 101 | AB41: 5/18 10.247.241.151로 변경(대덕->판교로 이전) | AC41: SSL 인증서 설치 여부 확인 필요 = 설치필요없슴
...

Sheet 비상연락망
A2: 구분 | B2: 시스템명 | C2: 고객사담당자 | D2: C&C담당자 | E2: 협력 | F2: 상주여부 | G2: 사번 | H2: 업체명 | I2: {=_xlfn.XLOOKUP(D2,비상연락망!B:L,비상연락망!B:B)} -> #VALUE! | J2: 메일주소 | K2: 외부메일주소 | L2: 비고(특이사항)
A3: 경영지원 | B3: HR G/W HCM G/W | C3: =VLOOKUP(B3,'서비스 Master'!$C$4:$P$62,14,FALSE) -> 김햇빛 | D3: =VLOOKUP(B3,'서비스 Master'!$C$4:$P$62,10,FALSE) -> 조래옥 | E3: =VLOOKUP(B3,'서비스 Master'!$C$4:$P$62,11,FALSE) -> 유원혁 | F3: 상주 | G3: I21026 | H3: 씨앤토트플러스 | I3: 010-2907-1408 | J3: wonhyuckyu@partner.sk.com
B4: MDM 시스템 | C4: =VLOOKUP(B4,'서비스 Master'!$C$4:$P$62,14,FALSE) -> 유현상 | D4: =VLOOKUP(B4,'서비스 Master'!$C$4:$P$62,10,FALSE) -> 이용재 | E4: =VLOOKUP(B4,'서비스 Master'!$C$4:$P$62,11,FALSE) -> 민준홍 | F4: 비상주 | G4: I24501 | H4: 에델웨이 | I4: 010-8637-0074 | J4: alswnsghd1234@partner.sk.com | K4: mjh@tobeway.com | L4: 5/8 현행화(송효경 퇴사로 대체)
B5: MDM 유지보수 | C5: =VLOOKUP(B5,'서비스 Master'!$C$4:$P$62,14,FALSE) -> 0 | D5: =VLOOKUP(B5,'서비스 Master'!$C$4:$P$62,10,FALSE) -> 0 | E5: =VLOOKUP(B5,'서비스 Master'!$C$4:$P$62,11,FALSE) -> 0 | L5: 솔루션 유지보수
B6: PMO | C6: =VLOOKUP(B6,'서비스 Master'!$C$4:$P$62,14,FALSE) -> 민석홍 | D6: =VLOOKUP(B6,'서비스 Master'!$C$4:$P$62,10,FALSE) -> 조래옥 | E6: =VLOOKUP(B6,'서비스 Master'!$C$4:$P$62,11,FALSE) -> 최문석/홍명기 | F6: 상주 | G6: I21079/I22361 | H6: 문경컨설팅/제이스랩 | I6: 010-5480-5049/010-4555-8783 | J6: moonseok.c@partner.sk.com; myungki.89@partner.sk.com | K6: myungki@hotmail.com
B7: RPA | C7: =VLOOKUP(B7,'서비스 Master'!$C$4:$P$62,14,FALSE) -> 김햇빛 | D7: =VLOOKUP(B7,'서비스 Master'!$C$4:$P$62,10,FALSE) -> 이인 | E7: =VLOOKUP(B7,'서비스 Master'!$C$4:$P$62,11,FALSE) -> 김건휘 | F7: 비상주 | G7: I23106/I23198 | H7: 아트만파트너스 | I7: 010-4818-3476 | J7: ttttuo@partner.sk.com | K7: ttttuo@myatman.com
B8: UI/UX | C8: =VLOOKUP(B8,'서비스 Master'!$C$4:$P$62,14,FALSE) -> 김햇빛 | D8: =VLOOKUP(B8,'서비스 Master'!$C$4:$P$62,10,FALSE) -> 조래옥 | E8: =VLOOKUP(B8,'서비스 Master'!$C$4:$P$62,11,FALSE) -> 양미라 | F8: 비상주 | G8: I21023/I24433 | H8: 엘리웍스 | I8: 010-2722-6946 | J8: mirazzan@partner.sk.com | K8: mirazzan1004@naver.com
B9: 구)e-HR | C9: =VLOOKUP(B9,'서비스 Master'!$C$4:$P$62,14,FALSE) -> 김햇빛 | D9: =VLOOKUP(B9,'서비스 Master'!$C$4:$P$62,10,FALSE) -> 조래옥 | E9: =VLOOKUP(B9,'서비스 Master'!$C$4:$P$62,11,FALSE) -> 정정배/김기정 | F9: 상주 | G9: I20607/I23957 | H9: 제이스랩 | I9: 010-3906-3063/010-3156-7763 | J9: psslumber@partner.sk.com; crush0sun.11@partner.sk.com | K9: psslumber@gmail.com; crush0sun@naver.com
B10: 데이터레이크 | C10: =VLOOKUP(B10,'서비스 Master'!$C$4:$P$62,14,FALSE) -> 민석홍 | D10: =VLOOKUP(B10,'서비스 Master'!$C$4:$P$62,10,FALSE) -> 조래옥 | E10: =VLOOKUP(B10,'서비스 Master'!$C$4:$P$62,11,FALSE) -> 경규민 | F10: 상주 | G10: I22455 | H10: 데이터다이나믹스 | I10: 010-8757-9520 | J10: kmkyung.26@partner.sk.com | K10: kyumin.kyung@data-dynamics.io
B11: 데이터포털 | C11: =VLOOKUP(B11,'서비스 Master'!$C$4:$P$62,14,FALSE) -> 민석홍 | D11: =VLOOKUP(B11,'서비스 Master'!$C$4:$P$62,10,FALSE) -> 조래옥 | E11: =VLOOKUP(B11,'서비스 Master'!$C$4:$P$62,11,FALSE) -> 구본호 | F11: 상주 | G11: I24462 | H11: 씨앤토트플러스 | I11: 010-5118-2520 | J11: abonno.55@partner.sk.com | K11: abonno@naver.com
B12: 데이터포털 유지보수 | C12: =VLOOKUP(B12,'서비스 Master'!$C$4:$P$62,14,FALSE) -> 0 | D12: =VLOOKUP(B12,'서비스 Master'!$C$4:$P$62,10,FALSE) -> 0 | E12: =VLOOKUP(B12,'서비스 Master'!$C$4:$P$62,11,FALSE) -> 0 | L12: 솔루션 유지보수
B13: 법무포탈 | C13: =VLOOKUP(B13,'서비스 Master'!$C$4:$P$62,14,FALSE) -> 김햇빛 | D13: =VLOOKUP(B13,'서비스 Master'!$C$4:$P$62,10,FALSE) -> 조래옥 | E13: 김아현 | F13: 비상주 | G13: I24733 | H13: 버텍스아이디 | I13: 010-2770-2956 | J13: ladkgus75.42@partner.sk.com | K13: rladkgus75@vertexid.com | L13: 박지은에서 변경
B14: 스마트오피스 서비스 | C14: =VLOOKUP(B14,'서비스 Master'!$C$4:$P$62,14,FALSE) -> 김햇빛 | D14: =VLOOKUP(B14,'서비스 Master'!$C$4:$P$62,10,FALSE) -> 조래옥 | E14: =VLOOKUP(B14,'서비스 Master'!$C$4:$P$62,11,FALSE) -> 변영운 | F14: 비상주 | G14: I23753 | H14: 동아피엠 | I14: 010-6568-3890 | J14: summer3890@partner.sk.com | K14: summer@dongapm.com | L14: 김우석에서 변경
A15: 기업문화 | B15: ESG Data HUB | C15: =VLOOKUP(B15,'서비스 Master'!$C$4:$P$62,14,FALSE) -> 김햇빛 | D15: =VLOOKUP(B15,'서비스 Master'!$C$4:$P$62,10,FALSE) -> 조래옥 | E15: 한준호 | F15: 비상주 | G15: I23886 | H15: 넥스트나우 | I15: 010-9901-7193 | J15: jh.han.22@partner.sk.com | K15: jh.han@nextnow.kr | L15: 김보성에서 변경
B16: 톡톡 스마트오피스 앱 | C16: =VLOOKUP(B16,'서비스 Master'!$C$4:$P$62,14,FALSE) -> 김햇빛 | D16: =VLOOKUP(B16,'서비스 Master'!$C$4:$P$62,10,FALSE) -> 조래옥 | E16: =VLOOKUP(B16,'서비스 Master'!$C$4:$P$62,11,FALSE) -> 정상률 | F16: 비상주 | G16: I21800 | H16: NTSoft | I16: 010-3070-2278 | J16: ryur0205@partner.sk.com | K16: ryur0205@ntsoft.kr | L16: 8/18 현행화(김은정 육아휴직으로 삭제)
A17: 영업 | B17: CRM (S.Square) | C17: =VLOOKUP(B17,'서비스 Master'!$C$4:$P$62,14,FALSE) -> 김햇빛 | D17: =VLOOKUP(B17,'서비스 Master'!$C$4:$P$62,10,FALSE) -> 이인 | E17: =VLOOKUP(B17,'서비스 Master'!$C$4:$P$62,11,FALSE) -> 박도현 | F17: 상주 | G17: I20913 | H17: 리아연구소 | I17: 010-7177-0716 | J17: dhpark0716@partner.sk.com | K17: dhpark@rialab.co.kr | L17: 25년 2분기 이후 계약 종료
B18: EOS G/W | C18: =VLOOKUP(B18,'서비스 Master'!$C$4:$P$62,14,FALSE) -> 박상진 | D18: =VLOOKUP(B18,'서비스 Master'!$C$4:$P$62,10,FALSE) -> 이인 | E18: =VLOOKUP(B18,'서비스 Master'!$C$4:$P$62,11,FALSE) -> 김기정 | F18: 상주 | G18: I23957 | H18: 제이스랩 | I18: 010-3156-7763 | J18: crush0sun.11@partner.sk.com | K18: crush0sun@naver.com
B19: SIRS | C19: =VLOOKUP(B19,'서비스 Master'!$C$4:$P$62,14,FALSE) -> 박상진 | D19: =VLOOKUP(B19,'서비스 Master'!$C$4:$P$62,10,FALSE) -> 이인 | E19: =VLOOKUP(B19,'서비스 Master'!$C$4:$P$62,11,FALSE) -> 김형일 | F19: 상주 | G19: I22148 | H19: 제이스랩 | I19: 010-8456-7946 | K19: hlkim7766@gmail.com
B20: SKMU 휴폐업 중계서버 | C20: =VLOOKUP(B20,'서비스 Master'!$C$4:$P$62,14,FALSE) -> 0 | D20: =VLOOKUP(B20,'서비스 Master'!$C$4:$P$62,10,FALSE) -> 0 | E20: =VLOOKUP(B20,'서비스 Master'!$C$4:$P$62,11,FALSE) -> 0 | J20: hlkim12@partner.sk.com | L20: 솔루션 유지보수(고객사 직계약)
B21: SK케미칼 휴폐업 중계서버 | C21: =VLOOKUP(B21,'서비스 Master'!$C$4:$P$62,14,FALSE) -> 0 | D21: =VLOOKUP(B21,'서비스 Master'!$C$4:$P$62,10,FALSE) -> 0 | E21: =VLOOKUP(B21,'서비스 Master'!$C$4:$P$62,11,FALSE) -> 0 | L21: 솔루션 유지보수(고객사 직계약)
B22: 마케팅 허브 G/W | C22: =VLOOKUP(B22,'서비스 Master'!$C$4:$P$62,14,FALSE) -> 박상진 | D22: =VLOOKUP(B22,'서비스 Master'!$C$4:$P$62,10,FALSE) -> 이인 | E22: =VLOOKUP(B22,'서비스 Master'!$C$4:$P$62,11,FALSE) -> 김형일 | F22: 상주 | G22: I22148 | H22: 제이스랩 | I22: 010-8456-7946 | J22: hlkim12@partner.sk.com | K22: hlkim7766@gmail.com
B23: 모바일MIS | C23: =VLOOKUP(B23,'서비스 Master'!$C$4:$P$62,14,FALSE) -> 박상진 | D23: =VLOOKUP(B23,'서비스 Master'!$C$4:$P$62,10,FALSE) -> 이인 | E23: =VLOOKUP(B23,'서비스 Master'!$C$4:$P$62,11,FALSE) -> 김형일 | F23: 상주 | G23: I22148 | H23: 제이스랩 | I23: 010-8456-7946 | J23: hlkim12@partner.sk.com | K23: hlkim7766@gmail.com
B24: 엔티스_MIS | C24: =VLOOKUP(B24,'서비스 Master'!$C$4:$P$62,14,FALSE) -> 명진 | D24: =VLOOKUP(B24,'서비스 Master'!$C$4:$P$62,10,FALSE) -> 이인 | E24: =VLOOKUP(B24,'서비스 Master'!$C$4:$P$62,11,FALSE) -> 최창길 | F24: 상주 | G24: I00015 | H24: 제이스랩 | I24: 010-5394-3985 | J24: skchem.i00015@partner.sk.com | K24: ma8665@hanmail.net
B25: 임가공포탈 | C25: =VLOOKUP(B25,'서비스 Master'!$C$4:$P$62,14,FALSE) -> 명진 | D25: =VLOOKUP(B25,'서비스 Master'!$C$4:$P$62,10,FALSE) -> 이용재 | E25: =VLOOKUP(B25,'서비스 Master'!$C$4:$P$62,11,FALSE) -> 구본호 | F25: 상주 | G25: I24462 | H25: 씨앤토트플러스 | I25: 010-5118-2520 | J25: abonno.55@partner.sk.com | K25: abonno@naver.com
B26: 콜센터 | C26: =VLOOKUP(B26,'서비스 Master'!$C$4:$P$62,14,FALSE) -> 박상진 | D26: =VLOOKUP(B26,'서비스 Master'!$C$4:$P$62,10,FALSE) -> 이인 | E26: =VLOOKUP(B26,'서비스 Master'!$C$4:$P$62,11,FALSE) -> 김은수 | F26: 비상주 | G26: I21298 | H26: 이든와이즈 | I26: 010-3369-9305 | J26: eskim@partner.sk.com | K26: eskim@idenwise.com
B27: 파마 MIS | C27: =VLOOKUP(B27,'서비스 Master'!$C$4:$P$62,14,FALSE) -> 박상진 | D27: =VLOOKUP(B27,'서비스 Master'!$C$4:$P$62,10,FALSE) -> 이인 | E27: =VLOOKUP(B27,'서비스 Master'!$C$4:$P$62,11,FALSE) -> 정정배/김기정 | F27: 상주 | G27: I20607/I23957 | H27: 제이스랩 | I27: 010-3906-3063/010-3156-7763 | J27: psslumber@partner.sk.com; crush0sun.11@partner.sk.com | K27: psslumber@gmail.com; crush0sun@naver.com
B28: 파마 SFE | C28: =VLOOKUP(B28,'서비스 Master'!$C$4:$P$62,14,FALSE) -> 박상진 | D28: =VLOOKUP(B28,'서비스 Master'!$C$4:$P$62,10,FALSE) -> 이인 | E28: =VLOOKUP(B28,'서비스 Master'!$C$4:$P$62,11,FALSE) -> 김형일 | F28: 상주 | G28: I22148 | H28: 제이스랩 | I28: 010-8456-7946 | J28: hlkim12@partner.sk.com | K28: hlkim7766@gmail.com
B29: 플라즈마 SFE | C29: =VLOOKUP(B29,'서비스 Master'!$C$4:$P$62,14,FALSE) -> 임준식 | D29: =VLOOKUP(B29,'서비스 Master'!$C$4:$P$62,10,FALSE) -> 이인 | E29: =VLOOKUP(B29,'서비스 Master'!$C$4:$P$62,11,FALSE) -> 최용진 | F29: 상주 | G29: I24377 | H29: 제이스랩 | I29: 010-9990-4875 | J29: wy273.53@partner.sk.com | K29: wy273@naver.com
B30: 플라즈마_MIS | C30: =VLOOKUP(B30,'서비스 Master'!$C$4:$P$62,14,FALSE) -> 임준식 | D30: =VLOOKUP(B30,'서비스 Master'!$C$4:$P$62,10,FALSE) -> 이인 | E30: =VLOOKUP(B30,'서비스 Master'!$C$4:$P$62,11,FALSE) -> 최창길 | F30: 상주 | G30: I00015 | H30: 제이스랩 | I30: 010-5394-3985 | J30: skchem.i00015@partner.sk.com | K30: ma8665@hanmail.net
A31: 재무 | B31: SKMU 세금계산서 | C31: =VLOOKUP(B31,'서비스 Master'!$C$4:$P$62,14,FALSE) -> 0 | D31: =VLOOKUP(B31,'서비스 Master'!$C$4:$P$62,10,FALSE) -> 0 | E31: =VLOOKUP(B31,'서비스 Master'!$C$4:$P$62,11,FALSE) -> 0 | L31: 솔루션 유지보수(고객사 직계약)
B32: SK케미칼 매입통합 | C32: =VLOOKUP(B32,'서비스 Master'!$C$4:$P$62,14,FALSE) -> 명진 | D32: =VLOOKUP(B32,'서비스 Master'!$C$4:$P$62,10,FALSE) -> 이인 | E32: =VLOOKUP(B32,'서비스 Master'!$C$4:$P$62,11,FALSE) -> 윤호정 | F32: 비상주 | G32: I22236 | H32: 비즈니스온커뮤니케이션 | I32: 010-2015-5681 | J32: sb-webjung0868.07@partner.sk.com | K32: webjung@businesson.co.kr
B33: 내부통제시스템 | C33: =VLOOKUP(B33,'서비스 Master'!$C$4:$P$62,14,FALSE) -> 명진 | D33: =VLOOKUP(B33,'서비스 Master'!$C$4:$P$62,10,FALSE) -> 이인 | E33: =VLOOKUP(B33,'서비스 Master'!$C$4:$P$62,11,FALSE) -> 김소영/황영주 | F33: 비상주 | G33: I23407/I23406 | H33: 아이티센 | I33: 02-580-6540/02-580-6539 | K33: icm@itcen.com ; sykim1@itcen.com; yjhwang@itcen.com | L33: 업무관련 메일은 icm@itcen.com 기술지원팀 공용메일로 전달 , 담당자는 2/17 현행화, 영업담당자 최혁준(010-4941-1296, hjchoi@itcen.com)
B34: 비용정산 | C34: =VLOOKUP(B34,'서비스 Master'!$C$4:$P$62,14,FALSE) -> 명진 | D34: =VLOOKUP(B34,'서비스 Master'!$C$4:$P$62,10,FALSE) -> 이인 | E34: =VLOOKUP(B34,'서비스 Master'!$C$4:$P$62,11,FALSE) -> 김민준 | F34: 상주 | G34: I22733 | H34: 인사이트온 | I34: 010-6222-2580 | J34: mj.kim.91@partner.sk.com | K34: minjun0620@gmail.com
B35: 비용정산 파투아 | C35: =VLOOKUP(B35,'서비스 Master'!$C$4:$P$62,14,FALSE) -> 명진 | D35: =VLOOKUP(B35,'서비스 Master'!$C$4:$P$62,10,FALSE) -> 이인 | E35: =VLOOKUP(B35,'서비스 Master'!$C$4:$P$62,11,FALSE) -> 박우선 | F35: 비상주 | G35: N/A | H35: 파투아 | I35: 070-7114-7364 | K35: wooseon@patuah.com | L35: 홍진우(070-7114-7341, spotlight88@patuah.com)에서 변경
B36: 비용정산(전자증빙) | C36: =VLOOKUP(B36,'서비스 Master'!$C$4:$P$62,14,FALSE) -> 명진 | D36: =VLOOKUP(B36,'서비스 Master'!$C$4:$P$62,10,FALSE) -> 이인 | E36: 정찬준 | F36: 비상주 | G36: I21257 | H36: 우남소프트 | I36: 010-7177-3330 | J36: lsmmoon@partner.sk.com | K36: jung1066@woonamsoft.com | L36: 이상민(010-3211-2773, lsmmoon@woonamsoft.com)에서 변경
B37: 전자세금계산서 | C37: =VLOOKUP(B37,'서비스 Master'!$C$4:$P$62,14,FALSE) -> 명진 | D37: =VLOOKUP(B37,'서비스 Master'!$C$4:$P$62,10,FALSE) -> 이인 | E37: =VLOOKUP(B37,'서비스 Master'!$C$4:$P$62,11,FALSE) -> 김학준/이기석 | F37: 비상주 | G37: I24934/I21249 | H37: 이씨뱅크 | I37: 010-4027-7203/010-9979-7961 | K37: k7203@ec-bank.net; yiga80@ec-bank.net | L37: 26/2/27 현행화 (정 김학준 추가, 부 이기석)
A38: R&D | B38: MSDS 서비스 | C38: =VLOOKUP(B38,'서비스 Master'!$C$4:$P$62,14,FALSE) -> 김햇빛 | D38: =VLOOKUP(B38,'서비스 Master'!$C$4:$P$62,10,FALSE) -> 이용재 | E38: =VLOOKUP(B38,'서비스 Master'!$C$4:$P$62,11,FALSE) -> 우은정 | F38: 비상주 | G38: I22935 | H38: 켐토피아 | I38: 070-4361-3022 | K38: eunjung.woo@chemtopia.net
B39: 디테일링서비스 | C39: =VLOOKUP(B39,'서비스 Master'!$C$4:$P$62,14,FALSE) -> 김햇빛 | D39: =VLOOKUP(B39,'서비스 Master'!$C$4:$P$62,10,FALSE) -> 이인 | E39: =VLOOKUP(B39,'서비스 Master'!$C$4:$P$62,11,FALSE) -> 최용진 | F39: 상주 | G39: I24377 | H39: 제이스랩 | I39: 010-9990-4875 | J39: wy273.53@partner.sk.com | K39: wy273@naver.com | L39: 미사용
B40: 특허관리시스템 | C40: =VLOOKUP(B40,'서비스 Master'!$C$4:$P$62,14,FALSE) -> 김햇빛 | D40: =VLOOKUP(B40,'서비스 Master'!$C$4:$P$62,10,FALSE) -> 이용재 | E40: 이대현 | F40: 비상주 | G40: I24830 | H40: 애니파이브 | I40: 010-7513-0768 | J40: leedh.02@partner.sk.com | K40: leedh@anyfive.com | L40: 25/11/17 김호연M→이대현M 변경
B41: 화학연구소 CMS | C41: =VLOOKUP(B41,'서비스 Master'!$C$4:$P$62,14,FALSE) -> 김햇빛 | D41: =VLOOKUP(B41,'서비스 Master'!$C$4:$P$62,10,FALSE) -> 이용재 | E41: =VLOOKUP(B41,'서비스 Master'!$C$4:$P$62,11,FALSE) -> 한만석 | F41: 비상주 | G41: I22679 | H41: 되고시스템 | I41: 010-9878-3771 | K41: hms8117@duegosystem.com | L41: 7/15 운영자 변경('25년 7월 부)
...

Sheet 메일링리스트
A2: 전체 | B2: =_xlfn.TEXTJOIN("; ", TRUE, B11:B73) -> wonhyuckyu@partner.sk.com; moonseok.c@partner.sk.com; myungki.89@partner.sk.com; psslumber@partner.sk.com; crush0sun.11@partner.sk.com; kmkyung.26@partner.sk.com; abonno.55@partner.sk.com; dhpark0716@partner.sk.com; crush0sun.11@partner.sk.com; hlkim12@partner.sk.com; skchem.i00015@partner.sk.com; wy273.53@partner.sk.com; mj.kim.91@partner.sk.com; zionex5@partner.sk.com; ljy7445@partner.sk.com; bongjin_choi.49@partner.sk.com; skchem.i00015@partner.sk.com; crush0sun.11@partner.sk.com; psslumber@partner.sk.com; v8pjh.29@partner.sk.com; kysno3@partner.sk.com; bemyace@partner.sk.com; mjh@tobeway.com; ttttuo@myatman.com; mirazzan1004@naver.com; rladkgus75@vertexid.com; summer@dongapm.com; jh.han@nextnow.kr; ryur0205@ntsoft.kr; eskim@idenwise.com; webjung@businesson.co.kr; icm@itcen.com ; sykim1@itcen.com; yjhwang@itcen.com; wooseon@patuah.com; jung1066@woonamsoft.com; k7203@ec-bank.net; yiga80@ec-bank.net; eunjung.woo@chemtopia.net; leedh@anyfive.com; hms8117@duegosystem.com; seulgi.choi@wisetechglobal.com
A3: 전체 값복사 | B3: wonhyuckyu@partner.sk.com; moonseok.c@partner.sk.com; myungki.89@partner.sk.com; psslumber@partner.sk.com; crush0sun.11@partner.sk.com; kmkyung.26@partner.sk.com; abonno.55@partner.sk.com; dhpark0716@partner.sk.com; crush0sun.11@partner.sk.com; hlkim12@partner.sk.com; skchem.i00015@partner.sk.com; wy273.53@partner.sk.com; mj.kim.91@partner.sk.com; zionex5@partner.sk.com; ljy7445@partner.sk.com; bongjin_choi.49@partner.sk.com; skchem.i00015@partner.sk.com; crush0sun.11@partner.sk.com; psslumber@partner.sk.com; v8pjh.29@partner.sk.com; kysno3@partner.sk.com; bemyace@partner.sk.com; mjh@tobeway.com; ttttuo@myatman.com; mirazzan1004@naver.com; rladkgus75@vertexid.com; summer@dongapm.com; jh.han@nextnow.kr; ryur0205@ntsoft.kr; eskim@idenwise.com; webjung@businesson.co.kr; icm@itcen.com ; sykim1@itcen.com; yjhwang@itcen.com; wooseon@patuah.com; jung1066@woonamsoft.com; k7203@ec-bank.net; yiga80@ec-bank.net; eunjung.woo@chemtopia.net; leedh@anyfive.com; hms8117@duegosystem.com; seulgi.choi@wisetechglobal.com
A4: 상주_사내 | B4: =_xlfn.TEXTJOIN("; ", TRUE, D11:D48) -> wonhyuckyu@partner.sk.com; moonseok.c@partner.sk.com; myungki.89@partner.sk.com; psslumber@partner.sk.com; crush0sun.11@partner.sk.com; kmkyung.26@partner.sk.com; abonno.55@partner.sk.com; dhpark0716@partner.sk.com; crush0sun.11@partner.sk.com; hlkim12@partner.sk.com; skchem.i00015@partner.sk.com; wy273.53@partner.sk.com; mj.kim.91@partner.sk.com; zionex5@partner.sk.com; ljy7445@partner.sk.com; bongjin_choi.49@partner.sk.com; skchem.i00015@partner.sk.com; crush0sun.11@partner.sk.com; psslumber@partner.sk.com; v8pjh.29@partner.sk.com; kysno3@partner.sk.com; bemyace@partner.sk.com
A5: 상주 값복사 | B5: wonhyuckyu@partner.sk.com; moonseok.c@partner.sk.com; myungki.89@partner.sk.com; psslumber@partner.sk.com; crush0sun.11@partner.sk.com; kmkyung.26@partner.sk.com; abonno.55@partner.sk.com; crush0sun.11@partner.sk.com; hlkim12@partner.sk.com; skchem.i00015@partner.sk.com; v8pjh.29@partner.sk.com; wy273.53@partner.sk.com; mj.kim.91@partner.sk.com; zionex5@partner.sk.com; ljy7445@partner.sk.com; jisoo_kim@partner.sk.com; skchem.i00015@partner.sk.com; crush0sun.11@partner.sk.com; psslumber@partner.sk.com; kysno3@partner.sk.com; bemyace@partner.sk.com; ttttuo@myatman.com
A6: 비상주 | B6: =_xlfn.TEXTJOIN("; ", TRUE, F11:F26) -> mjh@tobeway.com; ttttuo@myatman.com; mirazzan1004@naver.com; rladkgus75@vertexid.com; summer@dongapm.com; jh.han@nextnow.kr; ryur0205@ntsoft.kr; eskim@idenwise.com; webjung@businesson.co.kr; icm@itcen.com ; sykim1@itcen.com; yjhwang@itcen.com; wooseon@patuah.com; jung1066@woonamsoft.com; k7203@ec-bank.net; yiga80@ec-bank.net; eunjung.woo@chemtopia.net; leedh@anyfive.com; hms8117@duegosystem.com
A7: 비상주 값복사 | B7: alswnsghd1234@naver.com; ttttuo@myatman.com; mirazzan1004@naver.com; jieunp974@vertexid.com; summer@dongapm.com; bs.kim@nextnow.kr; ryur0205@ntsoft.kr; eskim@idenwise.com; webjung@businesson.co.kr; sykim1@itcen.com; yjhwang@itcen.com; spotlight88@patuah.com; lsmmoon@woonamsoft.com; yiga80@ec-bank.net; eunjung.woo@chemtopia.net; hykim@anyfive.com; hms8117@duegosystem.com
B10: 전체 | D10: 상주 | F10: 비상주
B11: wonhyuckyu@partner.sk.com | D11: wonhyuckyu@partner.sk.com | F11: mjh@tobeway.com
B12: moonseok.c@partner.sk.com; myungki.89@partner.sk.com | D12: moonseok.c@partner.sk.com; myungki.89@partner.sk.com | F12: ttttuo@myatman.com
B13: psslumber@partner.sk.com; crush0sun.11@partner.sk.com | D13: psslumber@partner.sk.com; crush0sun.11@partner.sk.com | F13: mirazzan1004@naver.com
B14: kmkyung.26@partner.sk.com | D14: kmkyung.26@partner.sk.com | F14: rladkgus75@vertexid.com
B15: abonno.55@partner.sk.com | D15: abonno.55@partner.sk.com | F15: summer@dongapm.com
B16: dhpark0716@partner.sk.com | D16: dhpark0716@partner.sk.com | F16: jh.han@nextnow.kr
B17: crush0sun.11@partner.sk.com | D17: crush0sun.11@partner.sk.com | F17: ryur0205@ntsoft.kr
B18: hlkim12@partner.sk.com | D18: hlkim12@partner.sk.com | F18: eskim@idenwise.com
B19: skchem.i00015@partner.sk.com | D19: skchem.i00015@partner.sk.com | F19: webjung@businesson.co.kr
B20: wy273.53@partner.sk.com | D20: wy273.53@partner.sk.com | F20: icm@itcen.com ; sykim1@itcen.com; yjhwang@itcen.com
B21: mj.kim.91@partner.sk.com | D21: mj.kim.91@partner.sk.com | F21: wooseon@patuah.com
... B27: v8pjh.29@partner.sk.com | D27: v8pjh.29@partner.sk.com | F27: seulgi.choi@wisetechglobal.com
B28: kysno3@partner.sk.com; bemyace@partner.sk.com | D28: kysno3@partner.sk.com; bemyace@partner.sk.com
B29: mjh@tobeway.com
B30: ttttuo@myatman.com
B31: mirazzan1004@naver.com
B32: rladkgus75@vertexid.com
B33: summer@dongapm.com
B34: jh.han@nextnow.kr
B35: ryur0205@ntsoft.kr
B36: eskim@idenwise.com
B37: webjung@businesson.co.kr
B38: icm@itcen.com ; sykim1@itcen.com; yjhwang@itcen.com
B39: wooseon@patuah.com
B40: jung1066@woonamsoft.com
... B45: seulgi.choi@wisetechglobal.com

Sheet Dataset
A1: 개발/운영 | B1: 인프라 구분 | C1: 네트웍 구분 | D1: 플랫폼 구분 | E1: 컴포넌트 유형 | F1: 라이선스 | G1: 설치방법
A2: 개발 | B2: On-Premise | C2: Server Farm | D2: WEB | E2: 내비게이션(메뉴, 내비게이션, 페이지, 탭 등) | F2: 무료 | G2: 설치형
A3: 운영 | B3: AWS | C3: DMZ | D3: CS | E3: 입력 및 폼(웹에디터, 파일 업/다운로드, 검색, 날짜 피커 등) | F3: 유료(영구) | G3: 접속형
A4: QA | D4: Mobile | E4: 컨테이너 및 레이아웃(모달, 다이알로그, 레이아웃 그리드 등) | F4: 유료(구독) | G4: Portable(무설치)
D5: 기타 | E5: 피드백 및 상태표시(로딩, 알림, 경고, 툴팁 등) | F5: 자체개발
E6: 데이터 표시(리포트, 차트, 그래프, 캘린더 등)
E7: 기타(파일변환(PDF/이미지), 지도, 미디어(오디오/비디오 플레이어) 등)
E8: 통신(FTP, SFTP, SCP등)

Sheet 인력 Master
A1: No. | B1: 소속 | C1: 회사 | D1: 이름 | E1: 상주/비상주 | F1: 정/부 | G1: 남 | H1: 여 | I1: 업무 | J1: 비고
A2: 1 | B2: ICT(ITSecPrj) | C2: 선양 GDC | D2: 김흠철 | E2: 비상주 | G2: 남 | I2: SAP Solman | J2: ICT(ERP) 변경 검토
A3: 2 | B3: ICT(DX) | C3: 에델웨이 | D3: 민준홍 | E3: 비상주 | G3: 남 | I3: =_xlfn.XLOOKUP(D3,비상연락망!E:E,비상연락망!B:B,"",0,1) -> MDM 시스템 | J3: ICT(비상주) 변경 검토
A4: 3 | B4: ICT(DX) | C4: 켐토피아 | D4: 우은정 | E4: 비상주 | H4: 여 | I4: =_xlfn.XLOOKUP(D4,비상연락망!E:E,비상연락망!B:B,"",0,1) -> MSDS 서비스 | J4: ICT(비상주) 변경 검토
A5: 4 | B5: ICT(ERP) | C5: UNIR | D5: 안용주 | E5: 비상주 | G5: 남 | I5: SAP Solman
A6: 5 | B6: ICT(ERP) | C6: 에스퍼트 | D6: 김광원 | E6: 상주 | G6: 남 | I6: ERP(CO)
A7: 6 | B7: ICT(ERP) | C7: 에스퍼트 | D7: 김윤성 | E7: 상주 | G7: 남 | I7: ERP(FI/TR)
A8: 7 | B8: ICT(ERP) | C8: 에스퍼트 | D8: 김정민 | E8: 상주 | G8: 남 | I8: ERP(QM)
A9: 8 | B9: ICT(ERP) | C9: 에스퍼트 | D9: 김태형 | E9: 상주 | G9: 남 | I9: SAP PO
A10: 9 | B10: ICT(ERP) | C10: 에스퍼트 | D10: 문경빈 | E10: 상주 | G10: 남 | I10: ERP(FI/TR)
A11: 10 | B11: ICT(ERP) | C11: 에스퍼트 | D11: 박나리 | E11: 비상주 | H11: 여 | I11: SAP PO | J11: 26년 비상주 전환
A12: 11 | B12: ICT(ERP) | C12: 에스퍼트 | D12: 박창석 | E12: 상주 | G12: 남 | I12: ERP(SD)
A13: 12 | B13: ICT(ERP) | C13: 에스퍼트 | D13: 백새롬 | E13: 상주 | H13: 여 | I13: SAP PO
A14: 13 | B14: ICT(ERP) | C14: 에스퍼트 | D14: 백승민 | E14: 상주 | H14: 여 | I14: ERP(FI/TR)
A15: 14 | B15: ICT(ERP) | C15: 에스퍼트 | D15: 서창우 | E15: 상주 | G15: 남 | I15: SAP PO
A16: 15 | B16: ICT(ERP) | C16: 에스퍼트 | D16: 윤라미 | E16: 상주 | H16: 여 | I16: ERP(MM)
A17: 16 | B17: ICT(ERP) | C17: 에스퍼트 | D17: 윤상훈 | E17: 상주 | G17: 남 | I17: ERP(SD)
A18: 17 | B18: ICT(ERP) | C18: 에스퍼트 | D18: 이용남 | E18: 상주 | G18: 남 | I18: ERP(PP)
A19: 18 | B19: ICT(ERP) | C19: 에스퍼트 | D19: 이윤형 | E19: 상주 | G19: 남 | I19: ERP(MM)
A20: 19 | B20: ICT(ERP) | C20: 에스퍼트 | D20: 장서율 | E20: 상주 | H20: 여 | I20: SAP PO
A21: 20 | B21: ICT(ERP) | C21: 에스퍼트 | D21: 정윤준 | E21: 상주 | G21: 남 | I21: ERP(FI/TR)
A22: 21 | B22: ICT(M365) | C22: SK AX | D22: 최근창 | E22: 비상주 | G22: 남 | I22: M365
